Workbook

Sheet คู่มือการใช้งาน
B2: คู่มือการกรอก AI Use Case Template (v2)
B4: โครงสร้างไฟล์
B5: 1-UseCase ทั้งหมด | C5: แผนกกรอกเอง — ข้อมูลพื้นฐานและข้อมูลที่ใช้คำนวณคะแนน (กรอกทุก Use Case)
B6: 2-รายละเอียดเทคนิค | C6: แผนกกรอกเอง — ข้อมูลเชิงเทคนิคสำหรับกำหนด Spec Hardware (กรอกทุก Use Case) ช่องชื่อ/แผนกระบบดึงมาจากชั้นที่ 1 ให้อัตโนมัติ
B7: 3-คะแนนและลำดับ | C7: ระบบคำนวณให้อัตโนมัติ — ไม่ต้องกรอกอะไรเลย ดูอย่างเดียว บอกว่าแต่ละ Use Case ได้กี่คะแนน อยู่ระดับไหน อันดับที่เท่าไหร่
B8: DATA | C8: รายการตัวเลือก Dropdown + ตารางแปลงตัวเลือกเป็นคะแนน + น้ำหนักและเกณฑ์ (ปรับได้)
B9: ขั้นตอนการใช้งาน
B10: ขั้นที่ 1 | C10: แต่ละแผนกกรอก sheet '1-UseCase ทั้งหมด' ให้ครบทุก Use Case ที่อยากได้
B11: ขั้นที่ 2 | C11: กรอก sheet '2-รายละเอียดเทคนิค' ต่อ โดยดูชื่อ Use Case ที่ระบบดึงมาให้แล้ว
B12: ขั้นที่ 3 | C12: เปิด sheet '3-คะแนนและลำดับ' ดูผล — ระบบจัดอันดับให้ทันทีโดยไม่ต้องกด
B13: ขั้นที่ 4 | C13: นำไฟล์เข้าระบบ AI Use Case Tool เพื่อให้ AI ทบทวนคะแนนอีกชั้น และวิเคราะห์ Spec Hardware / ประมาณราคา Server ของ Use Case อันดับต้นๆ
B14: กติกาการกรอก
B15: ช่องสีเหลือง | C15: ช่องที่ต้องกรอกเอง
B16: ช่องสีเขียวอ่อน | C16: ระบบเติมให้อัตโนมัติ ห้ามพิมพ์ทับ (ถ้าพิมพ์ทับ สูตรจะหายและข้อมูลจะไม่ตรงกัน)
B17: แถวสีเทา (แถวที่ 6) | C17: แถวตัวอย่าง อย่าลบทิ้ง ใช้ดูว่าควรกรอกละเอียดแค่ไหน (เป็นตัวเลขสมมติ)
B18: ช่องที่มีลูกศร | C18: ต้องเลือกจากรายการเท่านั้น ห้ามพิมพ์เอง เพราะระบบอ่านค่าไปแปลงเป็นคะแนน
B19: ไม่รู้คำตอบทำยังไง | C19: เลือก 'ยังไม่แน่ใจ' ดีกว่าเดาตัวเลขมั่ว เพราะตัวเลขที่เดาจะทำให้คะแนนผิดทั้งระบบ
B20: กรอกได้กี่ Use Case | C20: แถวที่ 7 ถึง 36 (30 Use Case) ถ้าต้องการมากกว่านี้ให้แจ้งส่วนกลาง
B21: สถานที่ตั้ง (คอลัมน์ AA) | C21: บริษัทเดียวมีหลายที่ตั้งได้ — ที่ตั้งคนละที่ถือว่าใช้ Server คนละเครื่อง ไม่มี Server กลางข้ามที่ตั้ง จึงต้องพิมพ์ชื่อที่ตั้งให้เหมือนกันทุกครั้ง (ไม่ได้คิดคะแนน) ที่ตั้งเดียวเว้นว่างได้
B22: คอลัมน์ที่ตรงกับ Excel Template เดิม (ยกมาครบ ไม่ได้ตัดทิ้ง)
B23: Existing Work | C23: -> คอลัมน์ G 'วิธีการทำงานปัจจุบัน' ในชั้นที่ 1
B24: Description for Redesign | C24: -> คอลัมน์ H 'แนวทางหลังนำ AI มาใช้' ในชั้นที่ 1
B25: Data Available from & by … | C25: -> คอลัมน์ K 'ข้อมูลที่มีอยู่ตอนนี้' ในชั้นที่ 1
B26: ปัญหาที่ต้องการแก้ / Output ที่คาดหวัง (แบบ GSK) | C26: -> คอลัมน์ F และ H ในชั้นที่ 1
B27: ข้อมูลเชิงปริมาณ + ความต้องการเชิงเทคนิค (แบบ GSK) | C27: -> ย้ายไปอยู่ชั้นที่ 2 ทั้งหมด พร้อมเพิ่มที่ขาด เช่น Peak concurrent, ประเภทข้อมูล Input, ขนาดคลังเอกสาร, ความต้องการ Fine-tune
B28: ข้อมูลแต่ละกลุ่มถูกนำไปใช้ทำอะไร
B29: ผลกระทบ (สีส้ม) | C29: ชั่วโมง/สัปดาห์ + มูลค่าความเสียหาย -> คะแนน Impact (น้ำหนัก 35%)
B30: ความพร้อมข้อมูล (สีเขียว) | C30: รูปแบบ + ย้อนหลัง + สิทธิ์ใช้ข้อมูล -> คะแนน Data (น้ำหนัก 25%)
B31: ความเป็นไปได้ (สีม่วง) | C31: ระบบเดิมที่ต้องเชื่อม + คนดูแลต่อ -> คะแนน Feasibility (น้ำหนัก 25%)
B32: ความเสี่ยง (สีแดง) | C32: ผลถ้า AI ผิด + การตรวจซ้ำ + ความลับข้อมูล -> คะแนน Risk (น้ำหนัก 15% กลับด้าน)
B33: ชั้นที่ 2 ทั้งหมด | C33: ใช้กำหนด Spec Hardware : Latency + ประเภทข้อมูล -> ตัดสินว่าต้องใช้ GPU หรือ CPU | Peak concurrent + Requests -> ตัดสินขนาดเครื่อง | ระดับความลับ -> มาตรการเข้ารหัส/จำกัดสิทธิ์ (ทุกงานรันบน On-premise ไม่ใช้ Cloud)
B35: หมายเหตุ : ข้อมูลในแถวตัวอย่าง (แถวสีเทา) เป็นตัวเลขสมมติเพื่อแสดงรูปแบบการกรอกเท่านั้น ไม่ใช่ข้อมูลจริงของบริษัท

Sheet 1-UseCase ทั้งหมด
A1: ชั้นที่ 1 : เก็บ Use Case ทั้งหมด (ทุก Use Case ต้องกรอก — ระบบใช้ข้อมูลนี้คำนวณคะแนนใน sheet '3-คะแนนและลำดับ')
A2: วิธีกรอก : กรอกเฉพาะช่องสีเหลืองตั้งแต่แถวที่ 7 ลงไป | แถวสีเทา (แถวที่ 6) คือตัวอย่าง อย่าลบ | ช่องที่มีลูกศรต้องเลือกจากรายการเท่านั้น เพราะระบบอ่านค่าไปแปลงเป็นคะแนน
A4: ข้อมูลพื้นฐาน | F4: อ้างอิงระบบคุณภาพ (QWP / SQP) | I4: ผลกระทบ (Impact) | N4: ความพร้อมข้อมูล (Data) | S4: ความเป็นไปได้ (Feasibility) | U4: ความเสี่ยง (Risk) | X4: แผน | AA4: สถานที่ตั้ง
A5: ลำดับ | B5: ชื่อ Use Case | C5: บริษัท | D5: หน่วยงานที่ใช้งาน | E5: ผู้รับผิดชอบ (Owner) | F5: เอกสาร QWP ที่อ้างอิง (รหัส / ชื่อเอกสาร) | G5: ตัวชี้วัด kQI / QI ที่เกี่ยวข้อง | H5: ขั้นตอนใน SQP ที่เกี่ยวข้อง | I5: ปัญหาหรือข้อจำกัดของงานในปัจจุบัน | J5: วิธีการปฏิบัติงานในปัจจุบัน (Existing Work) | K5: แนวทางการทำงานหลังนำ AI มาใช้ (Description for Redesign) | L5: ปริมาณเวลาที่ใช้กับงานนี้ในปัจจุบัน (รวมทุกคนในหน่วยงาน) | M5: มูลค่าความสูญเสียต่อปี (ของเสีย เคลม งานแก้ไข ค่าปรับ) | N5: ข้อมูลที่มีอยู่ในปัจจุบัน (Data Available) | O5: รูปแบบการจัดเก็บข้อมูลในปัจจุบัน | P5: ระยะเวลาข้อมูลย้อนหลังที่มี | Q5: ปริมาณข้อมูลโดยประมาณ นับเป็นรายการ : ภาพ / ใบ / ไฟล์ / ครั้ง / ล็อต (เฉพาะข้อมูลที่ทราบผลลัพธ์แล้ว) | R5: สิทธิ์ในการนำข้อมูลมาใช้พัฒนา AI | S5: ความจำเป็นในการเชื่อมต่อกับระบบเดิม (ERP / MES / ระบบที่ใช้งานอยู่) | T5: ผู้ดูแลระบบหลังส่งมอบ | U5: ผลกระทบเมื่อ AI ให้ผลลัพธ์ผิดพลาด | V5: ความจำเป็นในการตรวจสอบผลลัพธ์โดยบุคลากร | W5: ระดับชั้นความลับของข้อมูล | X5: ระดับความสำคัญตามความเห็นหน่วยงาน (ไม่นำไปคิดคะแนน) | Y5: กำหนดเวลาที่ต้องการใช้งาน (ไตรมาส / ปี) | Z5: หมายเหตุ | AA5: สถานที่ตั้งที่ใช้งาน (โรงงาน / สาขา)
A6: 1 | B6: Auto Inspection ตรวจคุณภาพชิ้นงานด้วย Machine Learning | C6: S.K.Polymer | D6: Production | E6: คุณสมชาย | F6: QWP-PRD-012 ตรวจสอบคุณภาพชิ้นงานก่อนส่งมอบ | G6: kQI-2 อัตราของเสียที่หลุดถึงลูกค้า | H6: ขั้นตอนที่ 4 ตรวจสอบชิ้นงานหลังถอดจากแม่พิมพ์ | I6: พนักงาน QC ตรวจชิ้นงานด้วยสายตา เกิดความล้าในช่วงบ่าย ทำให้ของเสียหลุดถึงลูกค้าเดือนละ 2-3 ครั้ง | J6: พนักงาน QC 3 คน ผลัดกันตรวจทุกล็อตด้วยสายตา เทียบกับชิ้นงานตัวอย่างมาตรฐาน และบันทึกผลลงแบบฟอร์มกระดาษ | K6: ติดตั้งกล้องที่สายพาน ให้ AI คัดแยกชิ้นงานดีและเสียอัตโนมัติแบบทันที ชิ้นงานที่ AI ไม่มั่นใจจึงส่งให้บุคลากรตรวจซ้ำ และบันทึกผลเข้าระบบแทนกระดาษ | L6: มากกว่า 40 ชั่วโมง/สัปดาห์ (มากกว่า 1 คนเต็มเวลา) | M6: 500,000 - 2,000,000 บาท/ปี | N6: มีภาพถ่ายชิ้นงานดีและเสียจัดเก็บไว้ในโทรศัพท์ของหัวหน้ากะ ประมาณ 2 ปี และแบบฟอร์มบันทึกผลตรวจแบบกระดาษ | O6: ภาพถ่าย / ไฟล์รูปภาพ | P6: 1 - 3 ปี - เพียงพอในระดับหนึ่ง | Q6: ประมาณ 4,000 ภาพ (ดี 3,000 / เสีย 1,000) | R6: ได้ทันที - ข้อมูลอยู่ในความดูแลของหน่วยงาน | S6: ไม่จำเป็น - ระบบทำงานแยกอิสระได้ | T6: มี - หน่วยงานมีผู้รับผิดชอบดูแลต่อ (ระบุชื่อในหมายเหตุ) | U6: สูง - ของเสียถึงมือลูกค้า เกิดอันตราย หรือผิดข้อกำหนดกฎหมาย | V6: สุ่มตรวจบางส่วน - เฉพาะรายการที่ AI ไม่มั่นใจ | W6: ภายในองค์กร - ห้ามเผยแพร่ออกนอกบริษัท | X6: สูง - ต้องการเร่งด่วน | Y6: ไตรมาส 2 ปี 2570 | Z6: คุณสมชายผ่านการอบรม Python มาแล้ว | AA6: โรงงานระยอง
A7: 1 | B7: Auto Inspection ตรวจสอบคุณภาพชิ้นงานด้วย Machine Learning (แยกสินค้าดี/เสีย) | C7: บริษัท เอส.เค.โพลีเมอร์ จำกัด | D7: Production (MOLDING) | F7: QWP-A07 การวางแผนและควบคุมการผลิต MOLDING | G7: % สินค้าโอนขึ้นคลัง > 98% % งานจบตามแผน > 98% % OEE > 80% | H7: ขั้นตอนที่ 11 ผลิตและควบคุมติดตามแผนการผลิต › 5 การตรวจสอบคุณภาพชิ้นงาน | J7: การตรวจสอบชิ้นงาน ตรวจสอบคุณภาพชิ้นงาน โดย ใช้การตรวจสอบด้วยสายตา | K7: ใช้เครื่อง Auto Inspection ในการตรวจสอบคุณภาพสินค้า โดยใช้ Machine Learning ในการทำให้เกิดการจดจำ สินค้า ดี และ เสีย เพื่อแยกออกจากกัน | N7: - รุปของสินค้าทั้งานดีและงานเสีย | Z7: แหล่งข้อมูล: ไฟล์ AI Transformation Plan (Prod) E&E.xlsx ชีต Prod (3)
A8: 2 | B8: AI จัดคนเข้าเครื่องตาม Skill Matrix แทนหัวหน้างาน (AI-Driven Manpower Allocation) | C8: บริษัท เอส.เค.โพลีเมอร์ จำกัด | D8: Production (MOLDING) | F8: QWP-A07 การวางแผนและควบคุมการผลิต MOLDING | G8: % สินค้าโอนขึ้นคลัง > 98% % งานจบตามแผน > 98% % OEE > 80% | H8: ขั้นตอนที่ 11 ผลิตและควบคุมติดตามแผนการผลิต › 7 การจัดคนเข้าทำงาน | I8: ไม่มีการ Optimizations ให้เกิด ประสิทธิภาพสูงสุด | J8: หัวหน้างาน จะจัดคนแบบ Mannual โดยใช้ข้อมูลการ Fix คน Fix เครื่อง และ ข้อมูล Part Training ที่ผูกไว้ด้วย Excel และใช้ระบบเตือน หลังจากที่เลือกไปแล้วโดย จะรู้ว่า พนักงานที่จัดไปอยู่ระดับใหน | K8: ให้ AI จัดคนแทนหัวหน้างานโดย ให้พิจารณาจาก ข้อมูล การ Fix คน Fix เครื่อง , ข้อมูล Part Training , ข้อมูลแผนการผลิตจาก MPS , ข้อมูลการมาทำงาน จาก Payroll และ และข้อมูล Performance , Good rate ของพนักงานรายคน เพื่อให้การจัดคนมีประสิทธิภาพสูงสุด | N8: - Part Training - ตาราง Fix คน Fix เครื่อง - ข้อมูลการมาทำงานจาก Payroll - ประวัติ ผลงาน ของพนักงาน รายบุคคล | Z8: แหล่งข้อมูล: ไฟล์ AI Transformation Plan (Prod) E&E.xlsx ชีต Prod (3) และชีต Man Alocation 1–3 (Workflow, Data requirement, ทางเลือกการพัฒนา 3 ระดับ)
A9: 3 | B9: Big Data ปิด LOT การผลิตอัตโนมัติ และวิเคราะห์แนวทางแก้ปัญหาการผลิต (Close Lot Analytics) | C9: บริษัท เอส.เค.โพลีเมอร์ จำกัด | D9: Production (MOLDING) | F9: QWP-A07 การวางแผนและควบคุมการผลิต MOLDING | G9: % สินค้าโอนขึ้นคลัง > 98% % งานจบตามแผน > 98% % OEE > 80% | H9: ขั้นตอนที่ 19 Close Lot Meeting › 1 ประชุมสรุปผลการผลิต | J9: ประชุมสรุปผลการผลิต โดยจะพิจารณา ผลการผลิตตามหัวข้อเหล่านี้ - % Yeild rate - % Cost - ประวัติ NC และCCR - Last Mold และ Last shot เพื่อประเมินความพร้องของการผลิตในแผนถัดไป | K9: สร้าง Big Data ให้มีความเชื่อมโยงกัน ทุกข้อมูล และ ให้ มีระบบการประเมิน ปิด Lot แบบ Auto และให้สามารถวิเคราะห์แนวทางการแก้ไขปัญหาที่เกิดขึ้นในการผลิต | N9: - % Yeild rate - % Cost - ประวัติ NC และCCR - ผลการตรวจสอบ Last Mold และ Last shot | Z9: แหล่งข้อมูล: ไฟล์ AI Transformation Plan (Prod) E&E.xlsx ชีต Prod (3)

Sheet 2-รายละเอียดเทคนิค
A1: ชั้นที่ 2 : รายละเอียดเทคนิค (กรอกทุก Use Case — ใช้กำหนด Spec Server ที่จะตั้งในบริษัท)
A2: Server เป็นเครื่องซื้อใหม่ ตั้งในบริษัท ทุกที่ตั้ง (โรงงาน/สาขา) มีเครื่องของตัวเอง ไม่ใช้ Cloud | เขียว = ระบบดึงมาให้ | เหลือง = แผนกกรอก | ฟ้า = ทีม AI/IT เติมให้ทีหลัง แผนกข้ามไปได้เลย
A4: ลิงก์อัตโนมัติจากชั้นที่ 1 | D4: โซน A : ปริมาณงาน (หน่วยงานผู้ใช้กรอก) | K4: โซน A : ความต้องการใช้งาน (หน่วยงานผู้ใช้กรอก) | O4: โซน A : ข้อกำหนดและงบประมาณ (หน่วยงานผู้ใช้กรอก) | S4: โซน B : ทีม AI / IT ดำเนินการภายหลัง — หน่วยงานผู้ใช้ไม่ต้องกรอก
A5: ลำดับ | B5: ชื่อ Use Case | C5: หน่วยงานที่ใช้งาน | D5: ลักษณะการเริ่มทำงานของระบบ | E5: ประเภทข้อมูลนำเข้า (Input) | F5: ประเภทงาน AI (ระบบคำนวณให้จากช่องซ้าย) | G5: จำนวนผู้ใช้งานต่อวัน | H5: จำนวนผู้ใช้งานพร้อมกันสูงสุด (Peak Concurrent) | I5: ปริมาณรายการที่ต้องประมวลผลต่อวัน 1 รายการ = 1 ชิ้น / ล็อต / คำถาม / เคส แล้วแต่ประเภทงาน | J5: จำนวนจุดตรวจหรือกล้องที่ทำงานพร้อมกัน (งานประมวลผลภาพ) | K5: ภาษาที่ต้องรองรับ | L5: เวลาตอบสนองที่ยอมรับได้ | M5: ช่วงเวลาที่ต้องให้บริการ | N5: ผลกระทบเมื่อระบบตอบสนองช้าลง ในช่วงที่มีการใช้งานหนาแน่น | O5: ระยะเวลาการจัดเก็บข้อมูล | P5: งบประมาณที่ตั้งไว้ (บาท) หากมี | Q5: ข้อจำกัดอื่นๆ และหมายเหตุ | R5: ผู้ให้ข้อมูล (หน่วยงาน) | S5: ปริมาณข้อมูลนำเข้าต่อวัน | T5: ขนาดคลังเอกสารทั้งหมด (สำหรับงานสืบค้น / RAG) | U5: ความละเอียดของภาพ | V5: รูปแบบการติดตั้ง (Server ภายในองค์กรเท่านั้น) | W5: ความจำเป็นในการปรับโมเดล ด้วยข้อมูลขององค์กร | X5: ความถี่ในการฝึกโมเดลใหม่
A6: =IF('1-UseCase ทั้งหมด'!B6="","",'1-UseCase ทั้งหมด'!A6) | B6: =IF('1-UseCase ทั้งหมด'!B6="","",'1-UseCase ทั้งหมด'!B6) | C6: =IF('1-UseCase ทั้งหมด'!B6="","",'1-UseCase ทั้งหมด'!D6) | D6: ทำงานอัตโนมัติต่อเนื่อง - ระบบทำงานเอง ไม่มีผู้เรียกใช้ | E6: ภาพถ่าย | F6: =IF($E6="","",IF($E6="ข้อความ / เอกสาร","งานภาษา (LLM)",IF($E6="ภาพถ่าย","งานภาพ (Vision)",IF($E6="เสียง","งานเสียง",IF($E6="วิดีโอ","งานภาพ (Vision)",IF($E6="ตัวเลข / ตาราง","งานตัวเลข (ML)",IF($E6="ผสมหลายประเภท","ผสม - ต้องดูรายละเอียด",""))))))) | G6: 1 - 10 คน | H6: 1 - 2 คน | I6: 1,000 - 10,000 รายการ | J6: 2 - 3 จุด | K6: ไม่เกี่ยวข้องกับภาษา | L6: ทันที - ไม่เกิน 2 วินาที (ตอบกลับในกระบวนการทันที) | M6: เวลาทำการ 8:00 - 18:00 น. | N6: กระทบมาก - ไม่สามารถล่าช้าหรือหยุดได้ (อยู่ในสายการผลิต) | O6: 2 - 3 ปี | P6: 500000 | Q6: ต้องติดตั้งกล้องที่สายพานเดิม พื้นที่ติดตั้งจำกัด | R6: คุณสมชาย | S6: 1 - 10 GB | T6: ไม่เกี่ยวข้อง - ไม่ใช่งานสืบค้นเอกสาร | U6: 1 - 5 ล้านพิกเซล | V6: ต้องติดตั้งที่หน้างาน - ติดตั้งข้างเครื่องจักรหรือสายพาน | W6: จำเป็น - ต้อง Fine-tune ด้วยข้อมูลหรือภาพขององค์กร | X6: ทุกไตรมาส
A7: =IF('1-UseCase ทั้งหมด'!B7="","",'1-UseCase ทั้งหมด'!A7) | B7: =IF('1-UseCase ทั้งหมด'!B7="","",'1-UseCase ทั้งหมด'!B7) | C7: =IF('1-UseCase ทั้งหมด'!B7="","",'1-UseCase ทั้งหมด'!D7) | F7: =IF($E7="","",IF($E7="ข้อความ / เอกสาร","งานภาษา (LLM)",IF($E7="ภาพถ่าย","งานภาพ (Vision)",IF($E7="เสียง","งานเสียง",IF($E7="วิดีโอ","งานภาพ (Vision)",IF($E7="ตัวเลข / ตาราง","งานตัวเลข (ML)",IF($E7="ผสมหลายประเภท","ผสม - ต้องดูรายละเอียด","")))))))
A8: =IF('1-UseCase ทั้งหมด'!B8="","",'1-UseCase ทั้งหมด'!A8) | B8: =IF('1-UseCase ทั้งหมด'!B8="","",'1-UseCase ทั้งหมด'!B8) | C8: =IF('1-UseCase ทั้งหมด'!B8="","",'1-UseCase ทั้งหมด'!D8) | F8: =IF($E8="","",IF($E8="ข้อความ / เอกสาร","งานภาษา (LLM)",IF($E8="ภาพถ่าย","งานภาพ (Vision)",IF($E8="เสียง","งานเสียง",IF($E8="วิดีโอ","งานภาพ (Vision)",IF($E8="ตัวเลข / ตาราง","งานตัวเลข (ML)",IF($E8="ผสมหลายประเภท","ผสม - ต้องดูรายละเอียด","")))))))
A9: =IF('1-UseCase ทั้งหมด'!B9="","",'1-UseCase ทั้งหมด'!A9) | B9: =IF('1-UseCase ทั้งหมด'!B9="","",'1-UseCase ทั้งหมด'!B9) | C9: =IF('1-UseCase ทั้งหมด'!B9="","",'1-UseCase ทั้งหมด'!D9) | F9: =IF($E9="","",IF($E9="ข้อความ / เอกสาร","งานภาษา (LLM)",IF($E9="ภาพถ่าย","งานภาพ (Vision)",IF($E9="เสียง","งานเสียง",IF($E9="วิดีโอ","งานภาพ (Vision)",IF($E9="ตัวเลข / ตาราง","งานตัวเลข (ML)",IF($E9="ผสมหลายประเภท","ผสม - ต้องดูรายละเอียด","")))))))
A10: =IF('1-UseCase ทั้งหมด'!B10="","",'1-UseCase ทั้งหมด'!A10) | B10: =IF('1-UseCase ทั้งหมด'!B10="","",'1-UseCase ทั้งหมด'!B10) | C10: =IF('1-UseCase ทั้งหมด'!B10="","",'1-UseCase ทั้งหมด'!D10) | F10: =IF($E10="","",IF($E10="ข้อความ / เอกสาร","งานภาษา (LLM)",IF($E10="ภาพถ่าย","งานภาพ (Vision)",IF($E10="เสียง","งานเสียง",IF($E10="วิดีโอ","งานภาพ (Vision)",IF($E10="ตัวเลข / ตาราง","งานตัวเลข (ML)",IF($E10="ผสมหลายประเภท","ผสม - ต้องดูรายละเอียด","")))))))
A11: =IF('1-UseCase ทั้งหมด'!B11="","",'1-UseCase ทั้งหมด'!A11) | B11: =IF('1-UseCase ทั้งหมด'!B11="","",'1-UseCase ทั้งหมด'!B11) | C11: =IF('1-UseCase ทั้งหมด'!B11="","",'1-UseCase ทั้งหมด'!D11) | F11: =IF($E11="","",IF($E11="ข้อความ / เอกสาร","งานภาษา (LLM)",IF($E11="ภาพถ่าย","งานภาพ (Vision)",IF($E11="เสียง","งานเสียง",IF($E11="วิดีโอ","งานภาพ (Vision)",IF($E11="ตัวเลข / ตาราง","งานตัวเลข (ML)",IF($E11="ผสมหลายประเภท","ผสม - ต้องดูรายละเอียด","")))))))
A12: =IF('1-UseCase ทั้งหมด'!B12="","",'1-UseCase ทั้งหมด'!A12) | B12: =IF('1-UseCase ทั้งหมด'!B12="","",'1-UseCase ทั้งหมด'!B12) | C12: =IF('1-UseCase ทั้งหมด'!B12="","",'1-UseCase ทั้งหมด'!D12) | F12: =IF($E12="","",IF($E12="ข้อความ / เอกสาร","งานภาษา (LLM)",IF($E12="ภาพถ่าย","งานภาพ (Vision)",IF($E12="เสียง","งานเสียง",IF($E12="วิดีโอ","งานภาพ (Vision)",IF($E12="ตัวเลข / ตาราง","งานตัวเลข (ML)",IF($E12="ผสมหลายประเภท","ผสม - ต้องดูรายละเอียด","")))))))
A13: =IF('1-UseCase ทั้งหมด'!B13="","",'1-UseCase ทั้งหมด'!A13) | B13: =IF('1-UseCase ทั้งหมด'!B13="","",'1-UseCase ทั้งหมด'!B13) | C13: =IF('1-UseCase ทั้งหมด'!B13="","",'1-UseCase ทั้งหมด'!D13) | F13: =IF($E13="","",IF($E13="ข้อความ / เอกสาร","งานภาษา (LLM)",IF($E13="ภาพถ่าย","งานภาพ (Vision)",IF($E13="เสียง","งานเสียง",IF($E13="วิดีโอ","งานภาพ (Vision)",IF($E13="ตัวเลข / ตาราง","งานตัวเลข (ML)",IF($E13="ผสมหลายประเภท","ผสม - ต้องดูรายละเอียด","")))))))
A14: =IF('1-UseCase ทั้งหมด'!B14="","",'1-UseCase ทั้งหมด'!A14) | B14: =IF('1-UseCase ทั้งหมด'!B14="","",'1-UseCase ทั้งหมด'!B14) | C14: =IF('1-UseCase ทั้งหมด'!B14="","",'1-UseCase ทั้งหมด'!D14) | F14: =IF($E14="","",IF($E14="ข้อความ / เอกสาร","งานภาษา (LLM)",IF($E14="ภาพถ่าย","งานภาพ (Vision)",IF($E14="เสียง","งานเสียง",IF($E14="วิดีโอ","งานภาพ (Vision)",IF($E14="ตัวเลข / ตาราง","งานตัวเลข (ML)",IF($E14="ผสมหลายประเภท","ผสม - ต้องดูรายละเอียด","")))))))
A15: =IF('1-UseCase ทั้งหมด'!B15="","",'1-UseCase ทั้งหมด'!A15) | B15: =IF('1-UseCase ทั้งหมด'!B15="","",'1-UseCase ทั้งหมด'!B15) | C15: =IF('1-UseCase ทั้งหมด'!B15="","",'1-UseCase ทั้งหมด'!D15) | F15: =IF($E15="","",IF($E15="ข้อความ / เอกสาร","งานภาษา (LLM)",IF($E15="ภาพถ่าย","งานภาพ (Vision)",IF($E15="เสียง","งานเสียง",IF($E15="วิดีโอ","งานภาพ (Vision)",IF($E15="ตัวเลข / ตาราง","งานตัวเลข (ML)",IF($E15="ผสมหลายประเภท","ผสม - ต้องดูรายละเอียด","")))))))
A16: =IF('1-UseCase ทั้งหมด'!B16="","",'1-UseCase ทั้งหมด'!A16) | B16: =IF('1-UseCase ทั้งหมด'!B16="","",'1-UseCase ทั้งหมด'!B16) | C16: =IF('1-UseCase ทั้งหมด'!B16="","",'1-UseCase ทั้งหมด'!D16) | F16: =IF($E16="","",IF($E16="ข้อความ / เอกสาร","งานภาษา (LLM)",IF($E16="ภาพถ่าย","งานภาพ (Vision)",IF($E16="เสียง","งานเสียง",IF($E16="วิดีโอ","งานภาพ (Vision)",IF($E16="ตัวเลข / ตาราง","งานตัวเลข (ML)",IF($E16="ผสมหลายประเภท","ผสม - ต้องดูรายละเอียด","")))))))
A17: =IF('1-UseCase ทั้งหมด'!B17="","",'1-UseCase ทั้งหมด'!A17) | B17: =IF('1-UseCase ทั้งหมด'!B17="","",'1-UseCase ทั้งหมด'!B17) | C17: =IF('1-UseCase ทั้งหมด'!B17="","",'1-UseCase ทั้งหมด'!D17) | F17: =IF($E17="","",IF($E17="ข้อความ / เอกสาร","งานภาษา (LLM)",IF($E17="ภาพถ่าย","งานภาพ (Vision)",IF($E17="เสียง","งานเสียง",IF($E17="วิดีโอ","งานภาพ (Vision)",IF($E17="ตัวเลข / ตาราง","งานตัวเลข (ML)",IF($E17="ผสมหลายประเภท","ผสม - ต้องดูรายละเอียด","")))))))
A18: =IF('1-UseCase ทั้งหมด'!B18="","",'1-UseCase ทั้งหมด'!A18) | B18: =IF('1-UseCase ทั้งหมด'!B18="","",'1-UseCase ทั้งหมด'!B18) | C18: =IF('1-UseCase ทั้งหมด'!B18="","",'1-UseCase ทั้งหมด'!D18) | F18: =IF($E18="","",IF($E18="ข้อความ / เอกสาร","งานภาษา (LLM)",IF($E18="ภาพถ่าย","งานภาพ (Vision)",IF($E18="เสียง","งานเสียง",IF($E18="วิดีโอ","งานภาพ (Vision)",IF($E18="ตัวเลข / ตาราง","งานตัวเลข (ML)",IF($E18="ผสมหลายประเภท","ผสม - ต้องดูรายละเอียด","")))))))
... A36: =IF('1-UseCase ทั้งหมด'!B36="","",'1-UseCase ทั้งหมด'!A36) | B36: =IF('1-UseCase ทั้งหมด'!B36="","",'1-UseCase ทั้งหมด'!B36) | C36: =IF('1-UseCase ทั้งหมด'!B36="","",'1-UseCase ทั้งหมด'!D36) | F36: =IF($E36="","",IF($E36="ข้อความ / เอกสาร","งานภาษา (LLM)",IF($E36="ภาพถ่าย","งานภาพ (Vision)",IF($E36="เสียง","งานเสียง",IF($E36="วิดีโอ","งานภาพ (Vision)",IF($E36="ตัวเลข / ตาราง","งานตัวเลข (ML)",IF($E36="ผสมหลายประเภท","ผสม - ต้องดูรายละเอียด","")))))))

Sheet 3-คะแนนและลำดับ
A1: ชั้นที่ 3 : คะแนนและลำดับความสำคัญ (ระบบคำนวณให้อัตโนมัติ — ห้ามพิมพ์ทับ)
A2: ทุกช่องในหน้านี้เป็นสูตร ดึงข้อมูลจาก sheet '1-UseCase ทั้งหมด' อัตโนมัติ | แถวสีเทา (แถวที่ 6) คือคะแนนของ Use Case ตัวอย่าง ไม่นับเข้าการจัดอันดับ | ถ้าอยากปรับน้ำหนักคะแนนหรือเกณฑ์แบ่งระดับ ให้ไปแก้ที่ sheet 'DATA' คอลัมน์ AH-AI (ตัวเลขสีน้ำเงิน)
A4: ข้อมูล Use Case | D4: Impact 35% | G4: Data 25% | K4: Feasibility 25% | N4: Risk 15% (กลับด้าน) | R4: ผลลัพธ์
A5: No. | B5: ชื่อ Use Case | C5: ฝ่าย / แผนก | D5: ชม./สัปดาห์ -> คะแนน | E5: มูลค่าเสียหาย -> คะแนน | F5: Impact (1-5) | G5: รูปแบบ ข้อมูล | H5: ย้อนหลัง | I5: สิทธิ์ใช้ ข้อมูล | J5: Data (1-5) | K5: ระบบเดิม | L5: คนดูแล ต่อ | M5: Feasibility (1-5) | N5: AI ผิด | O5: ตรวจซ้ำ | P5: ความลับ | Q5: Risk (1-5) | R5: คะแนนรวม (20-100) | S5: ระดับ | T5: อันดับ | U5: ช่องบังคับที่ยัง ไม่ได้กรอก (0 = ครบ)
A6: =IF('1-UseCase ทั้งหมด'!B6="","",'1-UseCase ทั้งหมด'!A6) | B6: =IF('1-UseCase ทั้งหมด'!B6="","",'1-UseCase ทั้งหมด'!B6) | C6: =IF('1-UseCase ทั้งหมด'!B6="","",'1-UseCase ทั้งหมด'!D6) | D6: =IF('1-UseCase ทั้งหมด'!B6="","",IFERROR(INDEX(DATA!$R$30:$R$34,MATCH('1-UseCase ทั้งหมด'!L6,DATA!$R$4:$R$8,0)),"")) | E6: =IF('1-UseCase ทั้งหมด'!B6="","",IFERROR(INDEX(DATA!$S$30:$S$34,MATCH('1-UseCase ทั้งหมด'!M6,DATA!$S$4:$S$8,0)),"")) | F6: =IF('1-UseCase ทั้งหมด'!B6="","",IF(D6="",IF(AND(E6<>"",E6<>"-"),E6,""),IF(AND(E6<>"",E6<>"-"),ROUND((D6+E6)/2,0),D6))) | G6: =IF('1-UseCase ทั้งหมด'!B6="","",IFERROR(INDEX(DATA!$B$30:$B$35,MATCH('1-UseCase ทั้งหมด'!O6,DATA!$B$4:$B$9,0)),"")) | H6: =IF('1-UseCase ทั้งหมด'!B6="","",IFERROR(INDEX(DATA!$C$30:$C$33,MATCH('1-UseCase ทั้งหมด'!P6,DATA!$C$4:$C$7,0)),"")) | I6: =IF('1-UseCase ทั้งหมด'!B6="","",IFERROR(INDEX(DATA!$D$30:$D$32,MATCH('1-UseCase ทั้งหมด'!R6,DATA!$D$4:$D$6,0)),"")) | J6: =IF('1-UseCase ทั้งหมด'!B6="","",IFERROR(ROUND(AVERAGE(G6:I6),0),"")) | K6: =IF('1-UseCase ทั้งหมด'!B6="","",IFERROR(INDEX(DATA!$E$30:$E$33,MATCH('1-UseCase ทั้งหมด'!S6,DATA!$E$4:$E$7,0)),"")) | L6: =IF('1-UseCase ทั้งหมด'!B6="","",IFERROR(INDEX(DATA!$F$30:$F$32,MATCH('1-UseCase ทั้งหมด'!T6,DATA!$F$4:$F$6,0)),"")) | M6: =IF('1-UseCase ทั้งหมด'!B6="","",IFERROR(ROUND(AVERAGE(K6:L6),0),"")) | N6: =IF('1-UseCase ทั้งหมด'!B6="","",IFERROR(INDEX(DATA!$G$30:$G$32,MATCH('1-UseCase ทั้งหมด'!U6,DATA!$G$4:$G$6,0)),"")) | O6: =IF('1-UseCase ทั้งหมด'!B6="","",IFERROR(INDEX(DATA!$H$30:$H$32,MATCH('1-UseCase ทั้งหมด'!V6,DATA!$H$4:$H$6,0)),"")) | P6: =IF('1-UseCase ทั้งหมด'!B6="","",IFERROR(INDEX(DATA!$I$30:$I$33,MATCH('1-UseCase ทั้งหมด'!W6,DATA!$I$4:$I$7,0)),"")) | Q6: =IF('1-UseCase ทั้งหมด'!B6="","",IFERROR(ROUND(AVERAGE(N6:P6),0),"")) | R6: =IF('1-UseCase ทั้งหมด'!B6="","",IF(U6>0,"",IFERROR(ROUND((F6*DATA!$AI$4+M6*DATA!$AI$5+J6*DATA!$AI$6+(6-Q6)*DATA!$AI$7)*20,1),""))) | S6: =IF('1-UseCase ทั้งหมด'!B6="","",IF(U6>0,"ข้อมูลไม่ครบ",IF(R6="","",IF(R6>=DATA!$AI$10,"สูง",IF(R6>=DATA!$AI$11,"กลาง","ต่ำ"))))) | T6: ตัวอย่าง | U6: =IF('1-UseCase ทั้งหมด'!B6="","",COUNTBLANK('1-UseCase ทั้งหมด'!L6)+COUNTBLANK('1-UseCase ทั้งหมด'!M6)+COUNTBLANK('1-UseCase ทั้งหมด'!O6)+COUNTBLANK('1-UseCase ทั้งหมด'!P6)+COUNTBLANK('1-UseCase ทั้งหมด'!R6)+COUNTBLANK('1-UseCase ทั้งหมด'!S6)+COUNTBLANK('1-UseCase ทั้งหมด'!T6)+COUNTBLANK('1-UseCase ทั้งหมด'!U6)+COUNTBLANK('1-UseCase ทั้งหมด'!V6)+COUNTBLANK('1-UseCase ทั้งหมด'!W6))
A7: =IF('1-UseCase ทั้งหมด'!B7="","",'1-UseCase ทั้งหมด'!A7) | B7: =IF('1-UseCase ทั้งหมด'!B7="","",'1-UseCase ทั้งหมด'!B7) | C7: =IF('1-UseCase ทั้งหมด'!B7="","",'1-UseCase ทั้งหมด'!D7) | D7: =IF('1-UseCase ทั้งหมด'!B7="","",IFERROR(INDEX(DATA!$R$30:$R$34,MATCH('1-UseCase ทั้งหมด'!L7,DATA!$R$4:$R$8,0)),"")) | E7: =IF('1-UseCase ทั้งหมด'!B7="","",IFERROR(INDEX(DATA!$S$30:$S$34,MATCH('1-UseCase ทั้งหมด'!M7,DATA!$S$4:$S$8,0)),"")) | F7: =IF('1-UseCase ทั้งหมด'!B7="","",IF(D7="",IF(AND(E7<>"",E7<>"-"),E7,""),IF(AND(E7<>"",E7<>"-"),ROUND((D7+E7)/2,0),D7))) | G7: =IF('1-UseCase ทั้งหมด'!B7="","",IFERROR(INDEX(DATA!$B$30:$B$35,MATCH('1-UseCase ทั้งหมด'!O7,DATA!$B$4:$B$9,0)),"")) | H7: =IF('1-UseCase ทั้งหมด'!B7="","",IFERROR(INDEX(DATA!$C$30:$C$33,MATCH('1-UseCase ทั้งหมด'!P7,DATA!$C$4:$C$7,0)),"")) | I7: =IF('1-UseCase ทั้งหมด'!B7="","",IFERROR(INDEX(DATA!$D$30:$D$32,MATCH('1-UseCase ทั้งหมด'!R7,DATA!$D$4:$D$6,0)),"")) | J7: =IF('1-UseCase ทั้งหมด'!B7="","",IFERROR(ROUND(AVERAGE(G7:I7),0),"")) | K7: =IF('1-UseCase ทั้งหมด'!B7="","",IFERROR(INDEX(DATA!$E$30:$E$33,MATCH('1-UseCase ทั้งหมด'!S7,DATA!$E$4:$E$7,0)),"")) | L7: =IF('1-UseCase ทั้งหมด'!B7="","",IFERROR(INDEX(DATA!$F$30:$F$32,MATCH('1-UseCase ทั้งหมด'!T7,DATA!$F$4:$F$6,0)),"")) | M7: =IF('1-UseCase ทั้งหมด'!B7="","",IFERROR(ROUND(AVERAGE(K7:L7),0),"")) | N7: =IF('1-UseCase ทั้งหมด'!B7="","",IFERROR(INDEX(DATA!$G$30:$G$32,MATCH('1-UseCase ทั้งหมด'!U7,DATA!$G$4:$G$6,0)),"")) | O7: =IF('1-UseCase ทั้งหมด'!B7="","",IFERROR(INDEX(DATA!$H$30:$H$32,MATCH('1-UseCase ทั้งหมด'!V7,DATA!$H$4:$H$6,0)),"")) | P7: =IF('1-UseCase ทั้งหมด'!B7="","",IFERROR(INDEX(DATA!$I$30:$I$33,MATCH('1-UseCase ทั้งหมด'!W7,DATA!$I$4:$I$7,0)),"")) | Q7: =IF('1-UseCase ทั้งหมด'!B7="","",IFERROR(ROUND(AVERAGE(N7:P7),0),"")) | R7: =IF('1-UseCase ทั้งหมด'!B7="","",IF(U7>0,"",IFERROR(ROUND((F7*DATA!$AI$4+M7*DATA!$AI$5+J7*DATA!$AI$6+(6-Q7)*DATA!$AI$7)*20,1),""))) | S7: =IF('1-UseCase ทั้งหมด'!B7="","",IF(U7>0,"ข้อมูลไม่ครบ",IF(R7="","",IF(R7>=DATA!$AI$10,"สูง",IF(R7>=DATA!$AI$11,"กลาง","ต่ำ"))))) | T7: =IF('1-UseCase ทั้งหมด'!B7="","",IF(R7="","",RANK(R7,$R$7:$R$36,0))) | U7: =IF('1-UseCase ทั้งหมด'!B7="","",COUNTBLANK('1-UseCase ทั้งหมด'!L7)+COUNTBLANK('1-UseCase ทั้งหมด'!M7)+COUNTBLANK('1-UseCase ทั้งหมด'!O7)+COUNTBLANK('1-UseCase ทั้งหมด'!P7)+COUNTBLANK('1-UseCase ทั้งหมด'!R7)+COUNTBLANK('1-UseCase ทั้งหมด'!S7)+COUNTBLANK('1-UseCase ทั้งหมด'!T7)+COUNTBLANK('1-UseCase ทั้งหมด'!U7)+COUNTBLANK('1-UseCase ทั้งหมด'!V7)+COUNTBLANK('1-UseCase ทั้งหมด'!W7))
A8: =IF('1-UseCase ทั้งหมด'!B8="","",'1-UseCase ทั้งหมด'!A8) | B8: =IF('1-UseCase ทั้งหมด'!B8="","",'1-UseCase ทั้งหมด'!B8) | C8: =IF('1-UseCase ทั้งหมด'!B8="","",'1-UseCase ทั้งหมด'!D8) | D8: =IF('1-UseCase ทั้งหมด'!B8="","",IFERROR(INDEX(DATA!$R$30:$R$34,MATCH('1-UseCase ทั้งหมด'!L8,DATA!$R$4:$R$8,0)),"")) | E8: =IF('1-UseCase ทั้งหมด'!B8="","",IFERROR(INDEX(DATA!$S$30:$S$34,MATCH('1-UseCase ทั้งหมด'!M8,DATA!$S$4:$S$8,0)),"")) | F8: =IF('1-UseCase ทั้งหมด'!B8="","",IF(D8="",IF(AND(E8<>"",E8<>"-"),E8,""),IF(AND(E8<>"",E8<>"-"),ROUND((D8+E8)/2,0),D8))) | G8: =IF('1-UseCase ทั้งหมด'!B8="","",IFERROR(INDEX(DATA!$B$30:$B$35,MATCH('1-UseCase ทั้งหมด'!O8,DATA!$B$4:$B$9,0)),"")) | H8: =IF('1-UseCase ทั้งหมด'!B8="","",IFERROR(INDEX(DATA!$C$30:$C$33,MATCH('1-UseCase ทั้งหมด'!P8,DATA!$C$4:$C$7,0)),"")) | I8: =IF('1-UseCase ทั้งหมด'!B8="","",IFERROR(INDEX(DATA!$D$30:$D$32,MATCH('1-UseCase ทั้งหมด'!R8,DATA!$D$4:$D$6,0)),"")) | J8: =IF('1-UseCase ทั้งหมด'!B8="","",IFERROR(ROUND(AVERAGE(G8:I8),0),"")) | K8: =IF('1-UseCase ทั้งหมด'!B8="","",IFERROR(INDEX(DATA!$E$30:$E$33,MATCH('1-UseCase ทั้งหมด'!S8,DATA!$E$4:$E$7,0)),"")) | L8: =IF('1-UseCase ทั้งหมด'!B8="","",IFERROR(INDEX(DATA!$F$30:$F$32,MATCH('1-UseCase ทั้งหมด'!T8,DATA!$F$4:$F$6,0)),"")) | M8: =IF('1-UseCase ทั้งหมด'!B8="","",IFERROR(ROUND(AVERAGE(K8:L8),0),"")) | N8: =IF('1-UseCase ทั้งหมด'!B8="","",IFERROR(INDEX(DATA!$G$30:$G$32,MATCH('1-UseCase ทั้งหมด'!U8,DATA!$G$4:$G$6,0)),"")) | O8: =IF('1-UseCase ทั้งหมด'!B8="","",IFERROR(INDEX(DATA!$H$30:$H$32,MATCH('1-UseCase ทั้งหมด'!V8,DATA!$H$4:$H$6,0)),"")) | P8: =IF('1-UseCase ทั้งหมด'!B8="","",IFERROR(INDEX(DATA!$I$30:$I$33,MATCH('1-UseCase ทั้งหมด'!W8,DATA!$I$4:$I$7,0)),"")) | Q8: =IF('1-UseCase ทั้งหมด'!B8="","",IFERROR(ROUND(AVERAGE(N8:P8),0),"")) | R8: =IF('1-UseCase ทั้งหมด'!B8="","",IF(U8>0,"",IFERROR(ROUND((F8*DATA!$AI$4+M8*DATA!$AI$5+J8*DATA!$AI$6+(6-Q8)*DATA!$AI$7)*20,1),""))) | S8: =IF('1-UseCase ทั้งหมด'!B8="","",IF(U8>0,"ข้อมูลไม่ครบ",IF(R8="","",IF(R8>=DATA!$AI$10,"สูง",IF(R8>=DATA!$AI$11,"กลาง","ต่ำ"))))) | T8: =IF('1-UseCase ทั้งหมด'!B8="","",IF(R8="","",RANK(R8,$R$7:$R$36,0))) | U8: =IF('1-UseCase ทั้งหมด'!B8="","",COUNTBLANK('1-UseCase ทั้งหมด'!L8)+COUNTBLANK('1-UseCase ทั้งหมด'!M8)+COUNTBLANK('1-UseCase ทั้งหมด'!O8)+COUNTBLANK('1-UseCase ทั้งหมด'!P8)+COUNTBLANK('1-UseCase ทั้งหมด'!R8)+COUNTBLANK('1-UseCase ทั้งหมด'!S8)+COUNTBLANK('1-UseCase ทั้งหมด'!T8)+COUNTBLANK('1-UseCase ทั้งหมด'!U8)+COUNTBLANK('1-UseCase ทั้งหมด'!V8)+COUNTBLANK('1-UseCase ทั้งหมด'!W8))
A9: =IF('1-UseCase ทั้งหมด'!B9="","",'1-UseCase ทั้งหมด'!A9) | B9: =IF('1-UseCase ทั้งหมด'!B9="","",'1-UseCase ทั้งหมด'!B9) | C9: =IF('1-UseCase ทั้งหมด'!B9="","",'1-UseCase ทั้งหมด'!D9) | D9: =IF('1-UseCase ทั้งหมด'!B9="","",IFERROR(INDEX(DATA!$R$30:$R$34,MATCH('1-UseCase ทั้งหมด'!L9,DATA!$R$4:$R$8,0)),"")) | E9: =IF('1-UseCase ทั้งหมด'!B9="","",IFERROR(INDEX(DATA!$S$30:$S$34,MATCH('1-UseCase ทั้งหมด'!M9,DATA!$S$4:$S$8,0)),"")) | F9: =IF('1-UseCase ทั้งหมด'!B9="","",IF(D9="",IF(AND(E9<>"",E9<>"-"),E9,""),IF(AND(E9<>"",E9<>"-"),ROUND((D9+E9)/2,0),D9))) | G9: =IF('1-UseCase ทั้งหมด'!B9="","",IFERROR(INDEX(DATA!$B$30:$B$35,MATCH('1-UseCase ทั้งหมด'!O9,DATA!$B$4:$B$9,0)),"")) | H9: =IF('1-UseCase ทั้งหมด'!B9="","",IFERROR(INDEX(DATA!$C$30:$C$33,MATCH('1-UseCase ทั้งหมด'!P9,DATA!$C$4:$C$7,0)),"")) | I9: =IF('1-UseCase ทั้งหมด'!B9="","",IFERROR(INDEX(DATA!$D$30:$D$32,MATCH('1-UseCase ทั้งหมด'!R9,DATA!$D$4:$D$6,0)),"")) | J9: =IF('1-UseCase ทั้งหมด'!B9="","",IFERROR(ROUND(AVERAGE(G9:I9),0),"")) | K9: =IF('1-UseCase ทั้งหมด'!B9="","",IFERROR(INDEX(DATA!$E$30:$E$33,MATCH('1-UseCase ทั้งหมด'!S9,DATA!$E$4:$E$7,0)),"")) | L9: =IF('1-UseCase ทั้งหมด'!B9="","",IFERROR(INDEX(DATA!$F$30:$F$32,MATCH('1-UseCase ทั้งหมด'!T9,DATA!$F$4:$F$6,0)),"")) | M9: =IF('1-UseCase ทั้งหมด'!B9="","",IFERROR(ROUND(AVERAGE(K9:L9),0),"")) | N9: =IF('1-UseCase ทั้งหมด'!B9="","",IFERROR(INDEX(DATA!$G$30:$G$32,MATCH('1-UseCase ทั้งหมด'!U9,DATA!$G$4:$G$6,0)),"")) | O9: =IF('1-UseCase ทั้งหมด'!B9="","",IFERROR(INDEX(DATA!$H$30:$H$32,MATCH('1-UseCase ทั้งหมด'!V9,DATA!$H$4:$H$6,0)),"")) | P9: =IF('1-UseCase ทั้งหมด'!B9="","",IFERROR(INDEX(DATA!$I$30:$I$33,MATCH('1-UseCase ทั้งหมด'!W9,DATA!$I$4:$I$7,0)),"")) | Q9: =IF('1-UseCase ทั้งหมด'!B9="","",IFERROR(ROUND(AVERAGE(N9:P9),0),"")) | R9: =IF('1-UseCase ทั้งหมด'!B9="","",IF(U9>0,"",IFERROR(ROUND((F9*DATA!$AI$4+M9*DATA!$AI$5+J9*DATA!$AI$6+(6-Q9)*DATA!$AI$7)*20,1),""))) | S9: =IF('1-UseCase ทั้งหมด'!B9="","",IF(U9>0,"ข้อมูลไม่ครบ",IF(R9="","",IF(R9>=DATA!$AI$10,"สูง",IF(R9>=DATA!$AI$11,"กลาง","ต่ำ"))))) | T9: =IF('1-UseCase ทั้งหมด'!B9="","",IF(R9="","",RANK(R9,$R$7:$R$36,0))) | U9: =IF('1-UseCase ทั้งหมด'!B9="","",COUNTBLANK('1-UseCase ทั้งหมด'!L9)+COUNTBLANK('1-UseCase ทั้งหมด'!M9)+COUNTBLANK('1-UseCase ทั้งหมด'!O9)+COUNTBLANK('1-UseCase ทั้งหมด'!P9)+COUNTBLANK('1-UseCase ทั้งหมด'!R9)+COUNTBLANK('1-UseCase ทั้งหมด'!S9)+COUNTBLANK('1-UseCase ทั้งหมด'!T9)+COUNTBLANK('1-UseCase ทั้งหมด'!U9)+COUNTBLANK('1-UseCase ทั้งหมด'!V9)+COUNTBLANK('1-UseCase ทั้งหมด'!W9))
A10: =IF('1-UseCase ทั้งหมด'!B10="","",'1-UseCase ทั้งหมด'!A10) | B10: =IF('1-UseCase ทั้งหมด'!B10="","",'1-UseCase ทั้งหมด'!B10) | C10: =IF('1-UseCase ทั้งหมด'!B10="","",'1-UseCase ทั้งหมด'!D10) | D10: =IF('1-UseCase ทั้งหมด'!B10="","",IFERROR(INDEX(DATA!$R$30:$R$34,MATCH('1-UseCase ทั้งหมด'!L10,DATA!$R$4:$R$8,0)),"")) | E10: =IF('1-UseCase ทั้งหมด'!B10="","",IFERROR(INDEX(DATA!$S$30:$S$34,MATCH('1-UseCase ทั้งหมด'!M10,DATA!$S$4:$S$8,0)),"")) | F10: =IF('1-UseCase ทั้งหมด'!B10="","",IF(D10="",IF(AND(E10<>"",E10<>"-"),E10,""),IF(AND(E10<>"",E10<>"-"),ROUND((D10+E10)/2,0),D10))) | G10: =IF('1-UseCase ทั้งหมด'!B10="","",IFERROR(INDEX(DATA!$B$30:$B$35,MATCH('1-UseCase ทั้งหมด'!O10,DATA!$B$4:$B$9,0)),"")) | H10: =IF('1-UseCase ทั้งหมด'!B10="","",IFERROR(INDEX(DATA!$C$30:$C$33,MATCH('1-UseCase ทั้งหมด'!P10,DATA!$C$4:$C$7,0)),"")) | I10: =IF('1-UseCase ทั้งหมด'!B10="","",IFERROR(INDEX(DATA!$D$30:$D$32,MATCH('1-UseCase ทั้งหมด'!R10,DATA!$D$4:$D$6,0)),"")) | J10: =IF('1-UseCase ทั้งหมด'!B10="","",IFERROR(ROUND(AVERAGE(G10:I10),0),"")) | K10: =IF('1-UseCase ทั้งหมด'!B10="","",IFERROR(INDEX(DATA!$E$30:$E$33,MATCH('1-UseCase ทั้งหมด'!S10,DATA!$E$4:$E$7,0)),"")) | L10: =IF('1-UseCase ทั้งหมด'!B10="","",IFERROR(INDEX(DATA!$F$30:$F$32,MATCH('1-UseCase ทั้งหมด'!T10,DATA!$F$4:$F$6,0)),"")) | M10: =IF('1-UseCase ทั้งหมด'!B10="","",IFERROR(ROUND(AVERAGE(K10:L10),0),"")) | N10: =IF('1-UseCase ทั้งหมด'!B10="","",IFERROR(INDEX(DATA!$G$30:$G$32,MATCH('1-UseCase ทั้งหมด'!U10,DATA!$G$4:$G$6,0)),"")) | O10: =IF('1-UseCase ทั้งหมด'!B10="","",IFERROR(INDEX(DATA!$H$30:$H$32,MATCH('1-UseCase ทั้งหมด'!V10,DATA!$H$4:$H$6,0)),"")) | P10: =IF('1-UseCase ทั้งหมด'!B10="","",IFERROR(INDEX(DATA!$I$30:$I$33,MATCH('1-UseCase ทั้งหมด'!W10,DATA!$I$4:$I$7,0)),"")) | Q10: =IF('1-UseCase ทั้งหมด'!B10="","",IFERROR(ROUND(AVERAGE(N10:P10),0),"")) | R10: =IF('1-UseCase ทั้งหมด'!B10="","",IF(U10>0,"",IFERROR(ROUND((F10*DATA!$AI$4+M10*DATA!$AI$5+J10*DATA!$AI$6+(6-Q10)*DATA!$AI$7)*20,1),""))) | S10: =IF('1-UseCase ทั้งหมด'!B10="","",IF(U10>0,"ข้อมูลไม่ครบ",IF(R10="","",IF(R10>=DATA!$AI$10,"สูง",IF(R10>=DATA!$AI$11,"กลาง","ต่ำ"))))) | T10: =IF('1-UseCase ทั้งหมด'!B10="","",IF(R10="","",RANK(R10,$R$7:$R$36,0))) | U10: =IF('1-UseCase ทั้งหมด'!B10="","",COUNTBLANK('1-UseCase ทั้งหมด'!L10)+COUNTBLANK('1-UseCase ทั้งหมด'!M10)+COUNTBLANK('1-UseCase ทั้งหมด'!O10)+COUNTBLANK('1-UseCase ทั้งหมด'!P10)+COUNTBLANK('1-UseCase ทั้งหมด'!R10)+COUNTBLANK('1-UseCase ทั้งหมด'!S10)+COUNTBLANK('1-UseCase ทั้งหมด'!T10)+COUNTBLANK('1-UseCase ทั้งหมด'!U10)+COUNTBLANK('1-UseCase ทั้งหมด'!V10)+COUNTBLANK('1-UseCase ทั้งหมด'!W10))
A11: =IF('1-UseCase ทั้งหมด'!B11="","",'1-UseCase ทั้งหมด'!A11) | B11: =IF('1-UseCase ทั้งหมด'!B11="","",'1-UseCase ทั้งหมด'!B11) | C11: =IF('1-UseCase ทั้งหมด'!B11="","",'1-UseCase ทั้งหมด'!D11) | D11: =IF('1-UseCase ทั้งหมด'!B11="","",IFERROR(INDEX(DATA!$R$30:$R$34,MATCH('1-UseCase ทั้งหมด'!L11,DATA!$R$4:$R$8,0)),"")) | E11: =IF('1-UseCase ทั้งหมด'!B11="","",IFERROR(INDEX(DATA!$S$30:$S$34,MATCH('1-UseCase ทั้งหมด'!M11,DATA!$S$4:$S$8,0)),"")) | F11: =IF('1-UseCase ทั้งหมด'!B11="","",IF(D11="",IF(AND(E11<>"",E11<>"-"),E11,""),IF(AND(E11<>"",E11<>"-"),ROUND((D11+E11)/2,0),D11))) | G11: =IF('1-UseCase ทั้งหมด'!B11="","",IFERROR(INDEX(DATA!$B$30:$B$35,MATCH('1-UseCase ทั้งหมด'!O11,DATA!$B$4:$B$9,0)),"")) | H11: =IF('1-UseCase ทั้งหมด'!B11="","",IFERROR(INDEX(DATA!$C$30:$C$33,MATCH('1-UseCase ทั้งหมด'!P11,DATA!$C$4:$C$7,0)),"")) | I11: =IF('1-UseCase ทั้งหมด'!B11="","",IFERROR(INDEX(DATA!$D$30:$D$32,MATCH('1-UseCase ทั้งหมด'!R11,DATA!$D$4:$D$6,0)),"")) | J11: =IF('1-UseCase ทั้งหมด'!B11="","",IFERROR(ROUND(AVERAGE(G11:I11),0),"")) | K11: =IF('1-UseCase ทั้งหมด'!B11="","",IFERROR(INDEX(DATA!$E$30:$E$33,MATCH('1-UseCase ทั้งหมด'!S11,DATA!$E$4:$E$7,0)),"")) | L11: =IF('1-UseCase ทั้งหมด'!B11="","",IFERROR(INDEX(DATA!$F$30:$F$32,MATCH('1-UseCase ทั้งหมด'!T11,DATA!$F$4:$F$6,0)),"")) | M11: =IF('1-UseCase ทั้งหมด'!B11="","",IFERROR(ROUND(AVERAGE(K11:L11),0),"")) | N11: =IF('1-UseCase ทั้งหมด'!B11="","",IFERROR(INDEX(DATA!$G$30:$G$32,MATCH('1-UseCase ทั้งหมด'!U11,DATA!$G$4:$G$6,0)),"")) | O11: =IF('1-UseCase ทั้งหมด'!B11="","",IFERROR(INDEX(DATA!$H$30:$H$32,MATCH('1-UseCase ทั้งหมด'!V11,DATA!$H$4:$H$6,0)),"")) | P11: =IF('1-UseCase ทั้งหมด'!B11="","",IFERROR(INDEX(DATA!$I$30:$I$33,MATCH('1-UseCase ทั้งหมด'!W11,DATA!$I$4:$I$7,0)),"")) | Q11: =IF('1-UseCase ทั้งหมด'!B11="","",IFERROR(ROUND(AVERAGE(N11:P11),0),"")) | R11: =IF('1-UseCase ทั้งหมด'!B11="","",IF(U11>0,"",IFERROR(ROUND((F11*DATA!$AI$4+M11*DATA!$AI$5+J11*DATA!$AI$6+(6-Q11)*DATA!$AI$7)*20,1),""))) | S11: =IF('1-UseCase ทั้งหมด'!B11="","",IF(U11>0,"ข้อมูลไม่ครบ",IF(R11="","",IF(R11>=DATA!$AI$10,"สูง",IF(R11>=DATA!$AI$11,"กลาง","ต่ำ"))))) | T11: =IF('1-UseCase ทั้งหมด'!B11="","",IF(R11="","",RANK(R11,$R$7:$R$36,0))) | U11: =IF('1-UseCase ทั้งหมด'!B11="","",COUNTBLANK('1-UseCase ทั้งหมด'!L11)+COUNTBLANK('1-UseCase ทั้งหมด'!M11)+COUNTBLANK('1-UseCase ทั้งหมด'!O11)+COUNTBLANK('1-UseCase ทั้งหมด'!P11)+COUNTBLANK('1-UseCase ทั้งหมด'!R11)+COUNTBLANK('1-UseCase ทั้งหมด'!S11)+COUNTBLANK('1-UseCase ทั้งหมด'!T11)+COUNTBLANK('1-UseCase ทั้งหมด'!U11)+COUNTBLANK('1-UseCase ทั้งหมด'!V11)+COUNTBLANK('1-UseCase ทั้งหมด'!W11))
A12: =IF('1-UseCase ทั้งหมด'!B12="","",'1-UseCase ทั้งหมด'!A12) | B12: =IF('1-UseCase ทั้งหมด'!B12="","",'1-UseCase ทั้งหมด'!B12) | C12: =IF('1-UseCase ทั้งหมด'!B12="","",'1-UseCase ทั้งหมด'!D12) | D12: =IF('1-UseCase ทั้งหมด'!B12="","",IFERROR(INDEX(DATA!$R$30:$R$34,MATCH('1-UseCase ทั้งหมด'!L12,DATA!$R$4:$R$8,0)),"")) | E12: =IF('1-UseCase ทั้งหมด'!B12="","",IFERROR(INDEX(DATA!$S$30:$S$34,MATCH('1-UseCase ทั้งหมด'!M12,DATA!$S$4:$S$8,0)),"")) | F12: =IF('1-UseCase ทั้งหมด'!B12="","",IF(D12="",IF(AND(E12<>"",E12<>"-"),E12,""),IF(AND(E12<>"",E12<>"-"),ROUND((D12+E12)/2,0),D12))) | G12: =IF('1-UseCase ทั้งหมด'!B12="","",IFERROR(INDEX(DATA!$B$30:$B$35,MATCH('1-UseCase ทั้งหมด'!O12,DATA!$B$4:$B$9,0)),"")) | H12: =IF('1-UseCase ทั้งหมด'!B12="","",IFERROR(INDEX(DATA!$C$30:$C$33,MATCH('1-UseCase ทั้งหมด'!P12,DATA!$C$4:$C$7,0)),"")) | I12: =IF('1-UseCase ทั้งหมด'!B12="","",IFERROR(INDEX(DATA!$D$30:$D$32,MATCH('1-UseCase ทั้งหมด'!R12,DATA!$D$4:$D$6,0)),"")) | J12: =IF('1-UseCase ทั้งหมด'!B12="","",IFERROR(ROUND(AVERAGE(G12:I12),0),"")) | K12: =IF('1-UseCase ทั้งหมด'!B12="","",IFERROR(INDEX(DATA!$E$30:$E$33,MATCH('1-UseCase ทั้งหมด'!S12,DATA!$E$4:$E$7,0)),"")) | L12: =IF('1-UseCase ทั้งหมด'!B12="","",IFERROR(INDEX(DATA!$F$30:$F$32,MATCH('1-UseCase ทั้งหมด'!T12,DATA!$F$4:$F$6,0)),"")) | M12: =IF('1-UseCase ทั้งหมด'!B12="","",IFERROR(ROUND(AVERAGE(K12:L12),0),"")) | N12: =IF('1-UseCase ทั้งหมด'!B12="","",IFERROR(INDEX(DATA!$G$30:$G$32,MATCH('1-UseCase ทั้งหมด'!U12,DATA!$G$4:$G$6,0)),"")) | O12: =IF('1-UseCase ทั้งหมด'!B12="","",IFERROR(INDEX(DATA!$H$30:$H$32,MATCH('1-UseCase ทั้งหมด'!V12,DATA!$H$4:$H$6,0)),"")) | P12: =IF('1-UseCase ทั้งหมด'!B12="","",IFERROR(INDEX(DATA!$I$30:$I$33,MATCH('1-UseCase ทั้งหมด'!W12,DATA!$I$4:$I$7,0)),"")) | Q12: =IF('1-UseCase ทั้งหมด'!B12="","",IFERROR(ROUND(AVERAGE(N12:P12),0),"")) | R12: =IF('1-UseCase ทั้งหมด'!B12="","",IF(U12>0,"",IFERROR(ROUND((F12*DATA!$AI$4+M12*DATA!$AI$5+J12*DATA!$AI$6+(6-Q12)*DATA!$AI$7)*20,1),""))) | S12: =IF('1-UseCase ทั้งหมด'!B12="","",IF(U12>0,"ข้อมูลไม่ครบ",IF(R12="","",IF(R12>=DATA!$AI$10,"สูง",IF(R12>=DATA!$AI$11,"กลาง","ต่ำ"))))) | T12: =IF('1-UseCase ทั้งหมด'!B12="","",IF(R12="","",RANK(R12,$R$7:$R$36,0))) | U12: =IF('1-UseCase ทั้งหมด'!B12="","",COUNTBLANK('1-UseCase ทั้งหมด'!L12)+COUNTBLANK('1-UseCase ทั้งหมด'!M12)+COUNTBLANK('1-UseCase ทั้งหมด'!O12)+COUNTBLANK('1-UseCase ทั้งหมด'!P12)+COUNTBLANK('1-UseCase ทั้งหมด'!R12)+COUNTBLANK('1-UseCase ทั้งหมด'!S12)+COUNTBLANK('1-UseCase ทั้งหมด'!T12)+COUNTBLANK('1-UseCase ทั้งหมด'!U12)+COUNTBLANK('1-UseCase ทั้งหมด'!V12)+COUNTBLANK('1-UseCase ทั้งหมด'!W12))
A13: =IF('1-UseCase ทั้งหมด'!B13="","",'1-UseCase ทั้งหมด'!A13) | B13: =IF('1-UseCase ทั้งหมด'!B13="","",'1-UseCase ทั้งหมด'!B13) | C13: =IF('1-UseCase ทั้งหมด'!B13="","",'1-UseCase ทั้งหมด'!D13) | D13: =IF('1-UseCase ทั้งหมด'!B13="","",IFERROR(INDEX(DATA!$R$30:$R$34,MATCH('1-UseCase ทั้งหมด'!L13,DATA!$R$4:$R$8,0)),"")) | E13: =IF('1-UseCase ทั้งหมด'!B13="","",IFERROR(INDEX(DATA!$S$30:$S$34,MATCH('1-UseCase ทั้งหมด'!M13,DATA!$S$4:$S$8,0)),"")) | F13: =IF('1-UseCase ทั้งหมด'!B13="","",IF(D13="",IF(AND(E13<>"",E13<>"-"),E13,""),IF(AND(E13<>"",E13<>"-"),ROUND((D13+E13)/2,0),D13))) | G13: =IF('1-UseCase ทั้งหมด'!B13="","",IFERROR(INDEX(DATA!$B$30:$B$35,MATCH('1-UseCase ทั้งหมด'!O13,DATA!$B$4:$B$9,0)),"")) | H13: =IF('1-UseCase ทั้งหมด'!B13="","",IFERROR(INDEX(DATA!$C$30:$C$33,MATCH('1-UseCase ทั้งหมด'!P13,DATA!$C$4:$C$7,0)),"")) | I13: =IF('1-UseCase ทั้งหมด'!B13="","",IFERROR(INDEX(DATA!$D$30:$D$32,MATCH('1-UseCase ทั้งหมด'!R13,DATA!$D$4:$D$6,0)),"")) | J13: =IF('1-UseCase ทั้งหมด'!B13="","",IFERROR(ROUND(AVERAGE(G13:I13),0),"")) | K13: =IF('1-UseCase ทั้งหมด'!B13="","",IFERROR(INDEX(DATA!$E$30:$E$33,MATCH('1-UseCase ทั้งหมด'!S13,DATA!$E$4:$E$7,0)),"")) | L13: =IF('1-UseCase ทั้งหมด'!B13="","",IFERROR(INDEX(DATA!$F$30:$F$32,MATCH('1-UseCase ทั้งหมด'!T13,DATA!$F$4:$F$6,0)),"")) | M13: =IF('1-UseCase ทั้งหมด'!B13="","",IFERROR(ROUND(AVERAGE(K13:L13),0),"")) | N13: =IF('1-UseCase ทั้งหมด'!B13="","",IFERROR(INDEX(DATA!$G$30:$G$32,MATCH('1-UseCase ทั้งหมด'!U13,DATA!$G$4:$G$6,0)),"")) | O13: =IF('1-UseCase ทั้งหมด'!B13="","",IFERROR(INDEX(DATA!$H$30:$H$32,MATCH('1-UseCase ทั้งหมด'!V13,DATA!$H$4:$H$6,0)),"")) | P13: =IF('1-UseCase ทั้งหมด'!B13="","",IFERROR(INDEX(DATA!$I$30:$I$33,MATCH('1-UseCase ทั้งหมด'!W13,DATA!$I$4:$I$7,0)),"")) | Q13: =IF('1-UseCase ทั้งหมด'!B13="","",IFERROR(ROUND(AVERAGE(N13:P13),0),"")) | R13: =IF('1-UseCase ทั้งหมด'!B13="","",IF(U13>0,"",IFERROR(ROUND((F13*DATA!$AI$4+M13*DATA!$AI$5+J13*DATA!$AI$6+(6-Q13)*DATA!$AI$7)*20,1),""))) | S13: =IF('1-UseCase ทั้งหมด'!B13="","",IF(U13>0,"ข้อมูลไม่ครบ",IF(R13="","",IF(R13>=DATA!$AI$10,"สูง",IF(R13>=DATA!$AI$11,"กลาง","ต่ำ"))))) | T13: =IF('1-UseCase ทั้งหมด'!B13="","",IF(R13="","",RANK(R13,$R$7:$R$36,0))) | U13: =IF('1-UseCase ทั้งหมด'!B13="","",COUNTBLANK('1-UseCase ทั้งหมด'!L13)+COUNTBLANK('1-UseCase ทั้งหมด'!M13)+COUNTBLANK('1-UseCase ทั้งหมด'!O13)+COUNTBLANK('1-UseCase ทั้งหมด'!P13)+COUNTBLANK('1-UseCase ทั้งหมด'!R13)+COUNTBLANK('1-UseCase ทั้งหมด'!S13)+COUNTBLANK('1-UseCase ทั้งหมด'!T13)+COUNTBLANK('1-UseCase ทั้งหมด'!U13)+COUNTBLANK('1-UseCase ทั้งหมด'!V13)+COUNTBLANK('1-UseCase ทั้งหมด'!W13))
A14: =IF('1-UseCase ทั้งหมด'!B14="","",'1-UseCase ทั้งหมด'!A14) | B14: =IF('1-UseCase ทั้งหมด'!B14="","",'1-UseCase ทั้งหมด'!B14) | C14: =IF('1-UseCase ทั้งหมด'!B14="","",'1-UseCase ทั้งหมด'!D14) | D14: =IF('1-UseCase ทั้งหมด'!B14="","",IFERROR(INDEX(DATA!$R$30:$R$34,MATCH('1-UseCase ทั้งหมด'!L14,DATA!$R$4:$R$8,0)),"")) | E14: =IF('1-UseCase ทั้งหมด'!B14="","",IFERROR(INDEX(DATA!$S$30:$S$34,MATCH('1-UseCase ทั้งหมด'!M14,DATA!$S$4:$S$8,0)),"")) | F14: =IF('1-UseCase ทั้งหมด'!B14="","",IF(D14="",IF(AND(E14<>"",E14<>"-"),E14,""),IF(AND(E14<>"",E14<>"-"),ROUND((D14+E14)/2,0),D14))) | G14: =IF('1-UseCase ทั้งหมด'!B14="","",IFERROR(INDEX(DATA!$B$30:$B$35,MATCH('1-UseCase ทั้งหมด'!O14,DATA!$B$4:$B$9,0)),"")) | H14: =IF('1-UseCase ทั้งหมด'!B14="","",IFERROR(INDEX(DATA!$C$30:$C$33,MATCH('1-UseCase ทั้งหมด'!P14,DATA!$C$4:$C$7,0)),"")) | I14: =IF('1-UseCase ทั้งหมด'!B14="","",IFERROR(INDEX(DATA!$D$30:$D$32,MATCH('1-UseCase ทั้งหมด'!R14,DATA!$D$4:$D$6,0)),"")) | J14: =IF('1-UseCase ทั้งหมด'!B14="","",IFERROR(ROUND(AVERAGE(G14:I14),0),"")) | K14: =IF('1-UseCase ทั้งหมด'!B14="","",IFERROR(INDEX(DATA!$E$30:$E$33,MATCH('1-UseCase ทั้งหมด'!S14,DATA!$E$4:$E$7,0)),"")) | L14: =IF('1-UseCase ทั้งหมด'!B14="","",IFERROR(INDEX(DATA!$F$30:$F$32,MATCH('1-UseCase ทั้งหมด'!T14,DATA!$F$4:$F$6,0)),"")) | M14: =IF('1-UseCase ทั้งหมด'!B14="","",IFERROR(ROUND(AVERAGE(K14:L14),0),"")) | N14: =IF('1-UseCase ทั้งหมด'!B14="","",IFERROR(INDEX(DATA!$G$30:$G$32,MATCH('1-UseCase ทั้งหมด'!U14,DATA!$G$4:$G$6,0)),"")) | O14: =IF('1-UseCase ทั้งหมด'!B14="","",IFERROR(INDEX(DATA!$H$30:$H$32,MATCH('1-UseCase ทั้งหมด'!V14,DATA!$H$4:$H$6,0)),"")) | P14: =IF('1-UseCase ทั้งหมด'!B14="","",IFERROR(INDEX(DATA!$I$30:$I$33,MATCH('1-UseCase ทั้งหมด'!W14,DATA!$I$4:$I$7,0)),"")) | Q14: =IF('1-UseCase ทั้งหมด'!B14="","",IFERROR(ROUND(AVERAGE(N14:P14),0),"")) | R14: =IF('1-UseCase ทั้งหมด'!B14="","",IF(U14>0,"",IFERROR(ROUND((F14*DATA!$AI$4+M14*DATA!$AI$5+J14*DATA!$AI$6+(6-Q14)*DATA!$AI$7)*20,1),""))) | S14: =IF('1-UseCase ทั้งหมด'!B14="","",IF(U14>0,"ข้อมูลไม่ครบ",IF(R14="","",IF(R14>=DATA!$AI$10,"สูง",IF(R14>=DATA!$AI$11,"กลาง","ต่ำ"))))) | T14: =IF('1-UseCase ทั้งหมด'!B14="","",IF(R14="","",RANK(R14,$R$7:$R$36,0))) | U14: =IF('1-UseCase ทั้งหมด'!B14="","",COUNTBLANK('1-UseCase ทั้งหมด'!L14)+COUNTBLANK('1-UseCase ทั้งหมด'!M14)+COUNTBLANK('1-UseCase ทั้งหมด'!O14)+COUNTBLANK('1-UseCase ทั้งหมด'!P14)+COUNTBLANK('1-UseCase ทั้งหมด'!R14)+COUNTBLANK('1-UseCase ทั้งหมด'!S14)+COUNTBLANK('1-UseCase ทั้งหมด'!T14)+COUNTBLANK('1-UseCase ทั้งหมด'!U14)+COUNTBLANK('1-UseCase ทั้งหมด'!V14)+COUNTBLANK('1-UseCase ทั้งหมด'!W14))
A15: =IF('1-UseCase ทั้งหมด'!B15="","",'1-UseCase ทั้งหมด'!A15) | B15: =IF('1-UseCase ทั้งหมด'!B15="","",'1-UseCase ทั้งหมด'!B15) | C15: =IF('1-UseCase ทั้งหมด'!B15="","",'1-UseCase ทั้งหมด'!D15) | D15: =IF('1-UseCase ทั้งหมด'!B15="","",IFERROR(INDEX(DATA!$R$30:$R$34,MATCH('1-UseCase ทั้งหมด'!L15,DATA!$R$4:$R$8,0)),"")) | E15: =IF('1-UseCase ทั้งหมด'!B15="","",IFERROR(INDEX(DATA!$S$30:$S$34,MATCH('1-UseCase ทั้งหมด'!M15,DATA!$S$4:$S$8,0)),"")) | F15: =IF('1-UseCase ทั้งหมด'!B15="","",IF(D15="",IF(AND(E15<>"",E15<>"-"),E15,""),IF(AND(E15<>"",E15<>"-"),ROUND((D15+E15)/2,0),D15))) | G15: =IF('1-UseCase ทั้งหมด'!B15="","",IFERROR(INDEX(DATA!$B$30:$B$35,MATCH('1-UseCase ทั้งหมด'!O15,DATA!$B$4:$B$9,0)),"")) | H15: =IF('1-UseCase ทั้งหมด'!B15="","",IFERROR(INDEX(DATA!$C$30:$C$33,MATCH('1-UseCase ทั้งหมด'!P15,DATA!$C$4:$C$7,0)),"")) | I15: =IF('1-UseCase ทั้งหมด'!B15="","",IFERROR(INDEX(DATA!$D$30:$D$32,MATCH('1-UseCase ทั้งหมด'!R15,DATA!$D$4:$D$6,0)),"")) | J15: =IF('1-UseCase ทั้งหมด'!B15="","",IFERROR(ROUND(AVERAGE(G15:I15),0),"")) | K15: =IF('1-UseCase ทั้งหมด'!B15="","",IFERROR(INDEX(DATA!$E$30:$E$33,MATCH('1-UseCase ทั้งหมด'!S15,DATA!$E$4:$E$7,0)),"")) | L15: =IF('1-UseCase ทั้งหมด'!B15="","",IFERROR(INDEX(DATA!$F$30:$F$32,MATCH('1-UseCase ทั้งหมด'!T15,DATA!$F$4:$F$6,0)),"")) | M15: =IF('1-UseCase ทั้งหมด'!B15="","",IFERROR(ROUND(AVERAGE(K15:L15),0),"")) | N15: =IF('1-UseCase ทั้งหมด'!B15="","",IFERROR(INDEX(DATA!$G$30:$G$32,MATCH('1-UseCase ทั้งหมด'!U15,DATA!$G$4:$G$6,0)),"")) | O15: =IF('1-UseCase ทั้งหมด'!B15="","",IFERROR(INDEX(DATA!$H$30:$H$32,MATCH('1-UseCase ทั้งหมด'!V15,DATA!$H$4:$H$6,0)),"")) | P15: =IF('1-UseCase ทั้งหมด'!B15="","",IFERROR(INDEX(DATA!$I$30:$I$33,MATCH('1-UseCase ทั้งหมด'!W15,DATA!$I$4:$I$7,0)),"")) | Q15: =IF('1-UseCase ทั้งหมด'!B15="","",IFERROR(ROUND(AVERAGE(N15:P15),0),"")) | R15: =IF('1-UseCase ทั้งหมด'!B15="","",IF(U15>0,"",IFERROR(ROUND((F15*DATA!$AI$4+M15*DATA!$AI$5+J15*DATA!$AI$6+(6-Q15)*DATA!$AI$7)*20,1),""))) | S15: =IF('1-UseCase ทั้งหมด'!B15="","",IF(U15>0,"ข้อมูลไม่ครบ",IF(R15="","",IF(R15>=DATA!$AI$10,"สูง",IF(R15>=DATA!$AI$11,"กลาง","ต่ำ"))))) | T15: =IF('1-UseCase ทั้งหมด'!B15="","",IF(R15="","",RANK(R15,$R$7:$R$36,0))) | U15: =IF('1-UseCase ทั้งหมด'!B15="","",COUNTBLANK('1-UseCase ทั้งหมด'!L15)+COUNTBLANK('1-UseCase ทั้งหมด'!M15)+COUNTBLANK('1-UseCase ทั้งหมด'!O15)+COUNTBLANK('1-UseCase ทั้งหมด'!P15)+COUNTBLANK('1-UseCase ทั้งหมด'!R15)+COUNTBLANK('1-UseCase ทั้งหมด'!S15)+COUNTBLANK('1-UseCase ทั้งหมด'!T15)+COUNTBLANK('1-UseCase ทั้งหมด'!U15)+COUNTBLANK('1-UseCase ทั้งหมด'!V15)+COUNTBLANK('1-UseCase ทั้งหมด'!W15))
A16: =IF('1-UseCase ทั้งหมด'!B16="","",'1-UseCase ทั้งหมด'!A16) | B16: =IF('1-UseCase ทั้งหมด'!B16="","",'1-UseCase ทั้งหมด'!B16) | C16: =IF('1-UseCase ทั้งหมด'!B16="","",'1-UseCase ทั้งหมด'!D16) | D16: =IF('1-UseCase ทั้งหมด'!B16="","",IFERROR(INDEX(DATA!$R$30:$R$34,MATCH('1-UseCase ทั้งหมด'!L16,DATA!$R$4:$R$8,0)),"")) | E16: =IF('1-UseCase ทั้งหมด'!B16="","",IFERROR(INDEX(DATA!$S$30:$S$34,MATCH('1-UseCase ทั้งหมด'!M16,DATA!$S$4:$S$8,0)),"")) | F16: =IF('1-UseCase ทั้งหมด'!B16="","",IF(D16="",IF(AND(E16<>"",E16<>"-"),E16,""),IF(AND(E16<>"",E16<>"-"),ROUND((D16+E16)/2,0),D16))) | G16: =IF('1-UseCase ทั้งหมด'!B16="","",IFERROR(INDEX(DATA!$B$30:$B$35,MATCH('1-UseCase ทั้งหมด'!O16,DATA!$B$4:$B$9,0)),"")) | H16: =IF('1-UseCase ทั้งหมด'!B16="","",IFERROR(INDEX(DATA!$C$30:$C$33,MATCH('1-UseCase ทั้งหมด'!P16,DATA!$C$4:$C$7,0)),"")) | I16: =IF('1-UseCase ทั้งหมด'!B16="","",IFERROR(INDEX(DATA!$D$30:$D$32,MATCH('1-UseCase ทั้งหมด'!R16,DATA!$D$4:$D$6,0)),"")) | J16: =IF('1-UseCase ทั้งหมด'!B16="","",IFERROR(ROUND(AVERAGE(G16:I16),0),"")) | K16: =IF('1-UseCase ทั้งหมด'!B16="","",IFERROR(INDEX(DATA!$E$30:$E$33,MATCH('1-UseCase ทั้งหมด'!S16,DATA!$E$4:$E$7,0)),"")) | L16: =IF('1-UseCase ทั้งหมด'!B16="","",IFERROR(INDEX(DATA!$F$30:$F$32,MATCH('1-UseCase ทั้งหมด'!T16,DATA!$F$4:$F$6,0)),"")) | M16: =IF('1-UseCase ทั้งหมด'!B16="","",IFERROR(ROUND(AVERAGE(K16:L16),0),"")) | N16: =IF('1-UseCase ทั้งหมด'!B16="","",IFERROR(INDEX(DATA!$G$30:$G$32,MATCH('1-UseCase ทั้งหมด'!U16,DATA!$G$4:$G$6,0)),"")) | O16: =IF('1-UseCase ทั้งหมด'!B16="","",IFERROR(INDEX(DATA!$H$30:$H$32,MATCH('1-UseCase ทั้งหมด'!V16,DATA!$H$4:$H$6,0)),"")) | P16: =IF('1-UseCase ทั้งหมด'!B16="","",IFERROR(INDEX(DATA!$I$30:$I$33,MATCH('1-UseCase ทั้งหมด'!W16,DATA!$I$4:$I$7,0)),"")) | Q16: =IF('1-UseCase ทั้งหมด'!B16="","",IFERROR(ROUND(AVERAGE(N16:P16),0),"")) | R16: =IF('1-UseCase ทั้งหมด'!B16="","",IF(U16>0,"",IFERROR(ROUND((F16*DATA!$AI$4+M16*DATA!$AI$5+J16*DATA!$AI$6+(6-Q16)*DATA!$AI$7)*20,1),""))) | S16: =IF('1-UseCase ทั้งหมด'!B16="","",IF(U16>0,"ข้อมูลไม่ครบ",IF(R16="","",IF(R16>=DATA!$AI$10,"สูง",IF(R16>=DATA!$AI$11,"กลาง","ต่ำ"))))) | T16: =IF('1-UseCase ทั้งหมด'!B16="","",IF(R16="","",RANK(R16,$R$7:$R$36,0))) | U16: =IF('1-UseCase ทั้งหมด'!B16="","",COUNTBLANK('1-UseCase ทั้งหมด'!L16)+COUNTBLANK('1-UseCase ทั้งหมด'!M16)+COUNTBLANK('1-UseCase ทั้งหมด'!O16)+COUNTBLANK('1-UseCase ทั้งหมด'!P16)+COUNTBLANK('1-UseCase ทั้งหมด'!R16)+COUNTBLANK('1-UseCase ทั้งหมด'!S16)+COUNTBLANK('1-UseCase ทั้งหมด'!T16)+COUNTBLANK('1-UseCase ทั้งหมด'!U16)+COUNTBLANK('1-UseCase ทั้งหมด'!V16)+COUNTBLANK('1-UseCase ทั้งหมด'!W16))
A17: =IF('1-UseCase ทั้งหมด'!B17="","",'1-UseCase ทั้งหมด'!A17) | B17: =IF('1-UseCase ทั้งหมด'!B17="","",'1-UseCase ทั้งหมด'!B17) | C17: =IF('1-UseCase ทั้งหมด'!B17="","",'1-UseCase ทั้งหมด'!D17) | D17: =IF('1-UseCase ทั้งหมด'!B17="","",IFERROR(INDEX(DATA!$R$30:$R$34,MATCH('1-UseCase ทั้งหมด'!L17,DATA!$R$4:$R$8,0)),"")) | E17: =IF('1-UseCase ทั้งหมด'!B17="","",IFERROR(INDEX(DATA!$S$30:$S$34,MATCH('1-UseCase ทั้งหมด'!M17,DATA!$S$4:$S$8,0)),"")) | F17: =IF('1-UseCase ทั้งหมด'!B17="","",IF(D17="",IF(AND(E17<>"",E17<>"-"),E17,""),IF(AND(E17<>"",E17<>"-"),ROUND((D17+E17)/2,0),D17))) | G17: =IF('1-UseCase ทั้งหมด'!B17="","",IFERROR(INDEX(DATA!$B$30:$B$35,MATCH('1-UseCase ทั้งหมด'!O17,DATA!$B$4:$B$9,0)),"")) | H17: =IF('1-UseCase ทั้งหมด'!B17="","",IFERROR(INDEX(DATA!$C$30:$C$33,MATCH('1-UseCase ทั้งหมด'!P17,DATA!$C$4:$C$7,0)),"")) | I17: =IF('1-UseCase ทั้งหมด'!B17="","",IFERROR(INDEX(DATA!$D$30:$D$32,MATCH('1-UseCase ทั้งหมด'!R17,DATA!$D$4:$D$6,0)),"")) | J17: =IF('1-UseCase ทั้งหมด'!B17="","",IFERROR(ROUND(AVERAGE(G17:I17),0),"")) | K17: =IF('1-UseCase ทั้งหมด'!B17="","",IFERROR(INDEX(DATA!$E$30:$E$33,MATCH('1-UseCase ทั้งหมด'!S17,DATA!$E$4:$E$7,0)),"")) | L17: =IF('1-UseCase ทั้งหมด'!B17="","",IFERROR(INDEX(DATA!$F$30:$F$32,MATCH('1-UseCase ทั้งหมด'!T17,DATA!$F$4:$F$6,0)),"")) | M17: =IF('1-UseCase ทั้งหมด'!B17="","",IFERROR(ROUND(AVERAGE(K17:L17),0),"")) | N17: =IF('1-UseCase ทั้งหมด'!B17="","",IFERROR(INDEX(DATA!$G$30:$G$32,MATCH('1-UseCase ทั้งหมด'!U17,DATA!$G$4:$G$6,0)),"")) | O17: =IF('1-UseCase ทั้งหมด'!B17="","",IFERROR(INDEX(DATA!$H$30:$H$32,MATCH('1-UseCase ทั้งหมด'!V17,DATA!$H$4:$H$6,0)),"")) | P17: =IF('1-UseCase ทั้งหมด'!B17="","",IFERROR(INDEX(DATA!$I$30:$I$33,MATCH('1-UseCase ทั้งหมด'!W17,DATA!$I$4:$I$7,0)),"")) | Q17: =IF('1-UseCase ทั้งหมด'!B17="","",IFERROR(ROUND(AVERAGE(N17:P17),0),"")) | R17: =IF('1-UseCase ทั้งหมด'!B17="","",IF(U17>0,"",IFERROR(ROUND((F17*DATA!$AI$4+M17*DATA!$AI$5+J17*DATA!$AI$6+(6-Q17)*DATA!$AI$7)*20,1),""))) | S17: =IF('1-UseCase ทั้งหมด'!B17="","",IF(U17>0,"ข้อมูลไม่ครบ",IF(R17="","",IF(R17>=DATA!$AI$10,"สูง",IF(R17>=DATA!$AI$11,"กลาง","ต่ำ"))))) | T17: =IF('1-UseCase ทั้งหมด'!B17="","",IF(R17="","",RANK(R17,$R$7:$R$36,0))) | U17: =IF('1-UseCase ทั้งหมด'!B17="","",COUNTBLANK('1-UseCase ทั้งหมด'!L17)+COUNTBLANK('1-UseCase ทั้งหมด'!M17)+COUNTBLANK('1-UseCase ทั้งหมด'!O17)+COUNTBLANK('1-UseCase ทั้งหมด'!P17)+COUNTBLANK('1-UseCase ทั้งหมด'!R17)+COUNTBLANK('1-UseCase ทั้งหมด'!S17)+COUNTBLANK('1-UseCase ทั้งหมด'!T17)+COUNTBLANK('1-UseCase ทั้งหมด'!U17)+COUNTBLANK('1-UseCase ทั้งหมด'!V17)+COUNTBLANK('1-UseCase ทั้งหมด'!W17))
A18: =IF('1-UseCase ทั้งหมด'!B18="","",'1-UseCase ทั้งหมด'!A18) | B18: =IF('1-UseCase ทั้งหมด'!B18="","",'1-UseCase ทั้งหมด'!B18) | C18: =IF('1-UseCase ทั้งหมด'!B18="","",'1-UseCase ทั้งหมด'!D18) | D18: =IF('1-UseCase ทั้งหมด'!B18="","",IFERROR(INDEX(DATA!$R$30:$R$34,MATCH('1-UseCase ทั้งหมด'!L18,DATA!$R$4:$R$8,0)),"")) | E18: =IF('1-UseCase ทั้งหมด'!B18="","",IFERROR(INDEX(DATA!$S$30:$S$34,MATCH('1-UseCase ทั้งหมด'!M18,DATA!$S$4:$S$8,0)),"")) | F18: =IF('1-UseCase ทั้งหมด'!B18="","",IF(D18="",IF(AND(E18<>"",E18<>"-"),E18,""),IF(AND(E18<>"",E18<>"-"),ROUND((D18+E18)/2,0),D18))) | G18: =IF('1-UseCase ทั้งหมด'!B18="","",IFERROR(INDEX(DATA!$B$30:$B$35,MATCH('1-UseCase ทั้งหมด'!O18,DATA!$B$4:$B$9,0)),"")) | H18: =IF('1-UseCase ทั้งหมด'!B18="","",IFERROR(INDEX(DATA!$C$30:$C$33,MATCH('1-UseCase ทั้งหมด'!P18,DATA!$C$4:$C$7,0)),"")) | I18: =IF('1-UseCase ทั้งหมด'!B18="","",IFERROR(INDEX(DATA!$D$30:$D$32,MATCH('1-UseCase ทั้งหมด'!R18,DATA!$D$4:$D$6,0)),"")) | J18: =IF('1-UseCase ทั้งหมด'!B18="","",IFERROR(ROUND(AVERAGE(G18:I18),0),"")) | K18: =IF('1-UseCase ทั้งหมด'!B18="","",IFERROR(INDEX(DATA!$E$30:$E$33,MATCH('1-UseCase ทั้งหมด'!S18,DATA!$E$4:$E$7,0)),"")) | L18: =IF('1-UseCase ทั้งหมด'!B18="","",IFERROR(INDEX(DATA!$F$30:$F$32,MATCH('1-UseCase ทั้งหมด'!T18,DATA!$F$4:$F$6,0)),"")) | M18: =IF('1-UseCase ทั้งหมด'!B18="","",IFERROR(ROUND(AVERAGE(K18:L18),0),"")) | N18: =IF('1-UseCase ทั้งหมด'!B18="","",IFERROR(INDEX(DATA!$G$30:$G$32,MATCH('1-UseCase ทั้งหมด'!U18,DATA!$G$4:$G$6,0)),"")) | O18: =IF('1-UseCase ทั้งหมด'!B18="","",IFERROR(INDEX(DATA!$H$30:$H$32,MATCH('1-UseCase ทั้งหมด'!V18,DATA!$H$4:$H$6,0)),"")) | P18: =IF('1-UseCase ทั้งหมด'!B18="","",IFERROR(INDEX(DATA!$I$30:$I$33,MATCH('1-UseCase ทั้งหมด'!W18,DATA!$I$4:$I$7,0)),"")) | Q18: =IF('1-UseCase ทั้งหมด'!B18="","",IFERROR(ROUND(AVERAGE(N18:P18),0),"")) | R18: =IF('1-UseCase ทั้งหมด'!B18="","",IF(U18>0,"",IFERROR(ROUND((F18*DATA!$AI$4+M18*DATA!$AI$5+J18*DATA!$AI$6+(6-Q18)*DATA!$AI$7)*20,1),""))) | S18: =IF('1-UseCase ทั้งหมด'!B18="","",IF(U18>0,"ข้อมูลไม่ครบ",IF(R18="","",IF(R18>=DATA!$AI$10,"สูง",IF(R18>=DATA!$AI$11,"กลาง","ต่ำ"))))) | T18: =IF('1-UseCase ทั้งหมด'!B18="","",IF(R18="","",RANK(R18,$R$7:$R$36,0))) | U18: =IF('1-UseCase ทั้งหมด'!B18="","",COUNTBLANK('1-UseCase ทั้งหมด'!L18)+COUNTBLANK('1-UseCase ทั้งหมด'!M18)+COUNTBLANK('1-UseCase ทั้งหมด'!O18)+COUNTBLANK('1-UseCase ทั้งหมด'!P18)+COUNTBLANK('1-UseCase ทั้งหมด'!R18)+COUNTBLANK('1-UseCase ทั้งหมด'!S18)+COUNTBLANK('1-UseCase ทั้งหมด'!T18)+COUNTBLANK('1-UseCase ทั้งหมด'!U18)+COUNTBLANK('1-UseCase ทั้งหมด'!V18)+COUNTBLANK('1-UseCase ทั้งหมด'!W18))
... A36: =IF('1-UseCase ทั้งหมด'!B36="","",'1-UseCase ทั้งหมด'!A36) | B36: =IF('1-UseCase ทั้งหมด'!B36="","",'1-UseCase ทั้งหมด'!B36) | C36: =IF('1-UseCase ทั้งหมด'!B36="","",'1-UseCase ทั้งหมด'!D36) | D36: =IF('1-UseCase ทั้งหมด'!B36="","",IFERROR(INDEX(DATA!$R$30:$R$34,MATCH('1-UseCase ทั้งหมด'!L36,DATA!$R$4:$R$8,0)),"")) | E36: =IF('1-UseCase ทั้งหมด'!B36="","",IFERROR(INDEX(DATA!$S$30:$S$34,MATCH('1-UseCase ทั้งหมด'!M36,DATA!$S$4:$S$8,0)),"")) | F36: =IF('1-UseCase ทั้งหมด'!B36="","",IF(D36="",IF(AND(E36<>"",E36<>"-"),E36,""),IF(AND(E36<>"",E36<>"-"),ROUND((D36+E36)/2,0),D36))) | G36: =IF('1-UseCase ทั้งหมด'!B36="","",IFERROR(INDEX(DATA!$B$30:$B$35,MATCH('1-UseCase ทั้งหมด'!O36,DATA!$B$4:$B$9,0)),"")) | H36: =IF('1-UseCase ทั้งหมด'!B36="","",IFERROR(INDEX(DATA!$C$30:$C$33,MATCH('1-UseCase ทั้งหมด'!P36,DATA!$C$4:$C$7,0)),"")) | I36: =IF('1-UseCase ทั้งหมด'!B36="","",IFERROR(INDEX(DATA!$D$30:$D$32,MATCH('1-UseCase ทั้งหมด'!R36,DATA!$D$4:$D$6,0)),"")) | J36: =IF('1-UseCase ทั้งหมด'!B36="","",IFERROR(ROUND(AVERAGE(G36:I36),0),"")) | K36: =IF('1-UseCase ทั้งหมด'!B36="","",IFERROR(INDEX(DATA!$E$30:$E$33,MATCH('1-UseCase ทั้งหมด'!S36,DATA!$E$4:$E$7,0)),"")) | L36: =IF('1-UseCase ทั้งหมด'!B36="","",IFERROR(INDEX(DATA!$F$30:$F$32,MATCH('1-UseCase ทั้งหมด'!T36,DATA!$F$4:$F$6,0)),"")) | M36: =IF('1-UseCase ทั้งหมด'!B36="","",IFERROR(ROUND(AVERAGE(K36:L36),0),"")) | N36: =IF('1-UseCase ทั้งหมด'!B36="","",IFERROR(INDEX(DATA!$G$30:$G$32,MATCH('1-UseCase ทั้งหมด'!U36,DATA!$G$4:$G$6,0)),"")) | O36: =IF('1-UseCase ทั้งหมด'!B36="","",IFERROR(INDEX(DATA!$H$30:$H$32,MATCH('1-UseCase ทั้งหมด'!V36,DATA!$H$4:$H$6,0)),"")) | P36: =IF('1-UseCase ทั้งหมด'!B36="","",IFERROR(INDEX(DATA!$I$30:$I$33,MATCH('1-UseCase ทั้งหมด'!W36,DATA!$I$4:$I$7,0)),"")) | Q36: =IF('1-UseCase ทั้งหมด'!B36="","",IFERROR(ROUND(AVERAGE(N36:P36),0),"")) | R36: =IF('1-UseCase ทั้งหมด'!B36="","",IF(U36>0,"",IFERROR(ROUND((F36*DATA!$AI$4+M36*DATA!$AI$5+J36*DATA!$AI$6+(6-Q36)*DATA!$AI$7)*20,1),""))) | S36: =IF('1-UseCase ทั้งหมด'!B36="","",IF(U36>0,"ข้อมูลไม่ครบ",IF(R36="","",IF(R36>=DATA!$AI$10,"สูง",IF(R36>=DATA!$AI$11,"กลาง","ต่ำ"))))) | T36: =IF('1-UseCase ทั้งหมด'!B36="","",IF(R36="","",RANK(R36,$R$7:$R$36,0))) | U36: =IF('1-UseCase ทั้งหมด'!B36="","",COUNTBLANK('1-UseCase ทั้งหมด'!L36)+COUNTBLANK('1-UseCase ทั้งหมด'!M36)+COUNTBLANK('1-UseCase ทั้งหมด'!O36)+COUNTBLANK('1-UseCase ทั้งหมด'!P36)+COUNTBLANK('1-UseCase ทั้งหมด'!R36)+COUNTBLANK('1-UseCase ทั้งหมด'!S36)+COUNTBLANK('1-UseCase ทั้งหมด'!T36)+COUNTBLANK('1-UseCase ทั้งหมด'!U36)+COUNTBLANK('1-UseCase ทั้งหมด'!V36)+COUNTBLANK('1-UseCase ทั้งหมด'!W36))
A38: เกณฑ์การแบ่งระดับ และสูตรที่ใช้
A39: • สูตร : คะแนนรวม = ( Impact x 35% + Feasibility x 25% + Data x 25% + (6 - Risk) x 15% ) x 20
A40: • Risk ถูกกลับด้านด้วย (6 - Risk) เพราะความเสี่ยงสูง = คะแนนควรต่ำ
A41: • ระดับ สูง = 75 คะแนนขึ้นไป | กลาง = 50 - 74 | ต่ำ = ต่ำกว่า 50 (คะแนนต่ำสุดที่เป็นไปได้คือ 20 ไม่ใช่ 0)
A42: • ถ้าช่องบังคับในชั้นที่ 1 ยังกรอกไม่ครบ ระบบจะไม่แสดงคะแนนรวม แต่ขึ้นว่า 'ข้อมูลไม่ครบ' และบอกจำนวนช่องที่ยังขาดในคอลัมน์สุดท้าย — กลับไปกรอกให้ครบแล้วคะแนนจะขึ้นเอง
A43: • ช่องบังคับ 10 ช่อง (คอลัมน์ L M O P R S T U V W) = เวลาที่ใช้ / มูลค่าความเสียหาย / รูปแบบข้อมูล / ข้อมูลย้อนหลัง / สิทธิ์ใช้ข้อมูล / ระบบเดิม / คนดูแลต่อ / ผลกระทบถ้า AI ผิด / การตรวจซ้ำ / ระดับความลับ
A44: • ถ้าตีมูลค่าความเสียหายเป็นเงินไม่ได้ ให้เลือก 'ประเมินเป็นเงินไม่ได้' — ระบบจะใช้เฉพาะชั่วโมงคิด Impact ไม่ได้หักคะแนน (ในตารางจะขึ้นเป็น '-')
A45: • คะแนนนี้เป็นตัวช่วยกรองเบื้องต้น ไม่ใช่คำตอบสุดท้าย — ผู้บริหารควรพิจารณา Use Case อันดับต้นๆ ด้วยตนเองอีกครั้ง
A46: • ค่าเกณฑ์ชั่วโมง/มูลค่า และน้ำหนักทุกตัว แก้ได้ที่ sheet DATA คอลัมน์ AH-AI (ตัวเลขสีน้ำเงิน)

Sheet DATA
A1: รายการตัวเลือก (Dropdown) — เพิ่ม/แก้ตัวเลือกได้ที่นี่ แล้วทุก sheet จะเปลี่ยนตาม | AH1: ค่าตั้งต้นของการคำนวณคะแนน (แก้ได้ ทุกสูตรจะเปลี่ยนตาม)
A3: บริษัท | B3: รูปแบบการจัดเก็บข้อมูลปัจจุบัน | C3: ระยะเวลาข้อมูลย้อนหลังที่มี | D3: สิทธิ์ในการนำข้อมูลมาใช้ | E3: การเชื่อมต่อกับระบบเดิม | F3: ผู้ดูแลระบบหลังส่งมอบ | G3: ผลกระทบเมื่อ AI ผิดพลาด | H3: การตรวจสอบผลลัพธ์โดยบุคลากร | I3: ระดับชั้นความลับของข้อมูล | J3: ระดับความสำคัญตามความเห็นผู้ใช้ | K3: ประเภทข้อมูลนำเข้า | L3: ภาษาที่ต้องรองรับ | M3: เวลาตอบสนองที่ยอมรับได้ | N3: ช่วงเวลาที่ต้องให้บริการ | O3: ความละเอียดของภาพ | Q3: การปรับโมเดลด้วยข้อมูลองค์กร | R3: เวลาที่ใช้กับงานนี้ในปัจจุบัน | S3: มูลค่าความสูญเสียต่อปี | T3: จำนวนผู้ใช้งานต่อวัน | U3: ผู้ใช้งานพร้อมกันสูงสุด | V3: ปริมาณรายการที่ประมวลผลต่อวัน | W3: ปริมาณข้อมูลนำเข้าต่อวัน | X3: ขนาดคลังเอกสารทั้งหมด | Y3: จุดตรวจที่ทำงานพร้อมกัน | Z3: รูปแบบการติดตั้ง | AB3: ระยะเวลาการจัดเก็บข้อมูล | AC3: ความถี่ในการฝึกโมเดลใหม่ | AD3: ผลกระทบเมื่อระบบตอบสนองช้าลง | AE3: ลักษณะการเริ่มทำงานของระบบ | AH3: น้ำหนักแต่ละปัจจัย
A4: บริษัท แกรนด์เอสเค คอร์ปอเรชั่น จำกัด | B4: เอกสารกระดาษ / บันทึกด้วยลายมือ - ต้องแปลงเป็นดิจิทัลก่อน | C4: ไม่มีข้อมูลย้อนหลัง - ต้องเริ่มเก็บใหม่ | D4: ได้ทันที - ข้อมูลอยู่ในความดูแลของหน่วยงาน | E4: ไม่จำเป็น - ระบบทำงานแยกอิสระได้ | F4: มี - หน่วยงานมีผู้รับผิดชอบดูแลต่อ (ระบุชื่อในหมายเหตุ) | G4: ต่ำ - ตรวจพบและแก้ไขได้ทันที ไม่กระทบผู้อื่น | H4: ไม่จำเป็น - ใช้ผลลัพธ์จาก AI ได้ทันที | I4: สาธารณะ - เปิดเผยได้ ไม่มีผลกระทบ | J4: สูง - ต้องการเร่งด่วน | K4: ข้อความ / เอกสาร | L4: ไทย | M4: ทันที - ไม่เกิน 2 วินาที (ตอบกลับในกระบวนการทันที) | N4: เวลาทำการ 8:00 - 18:00 น. | O4: ไม่เกี่ยวข้อง | Q4: ไม่จำเป็น - ใช้โมเดลสำเร็จรูปได้ (งานความรู้ทั่วไป) | R4: น้อยกว่า 4 ชั่วโมง/สัปดาห์ (ไม่ถึงครึ่งวันทำงาน) | S4: ไม่สามารถประเมินเป็นตัวเงินได้ หรือไม่มีความสูญเสียโดยตรง | T4: 1 - 10 คน | U4: 1 - 2 คน | V4: น้อยกว่า 100 รายการ | W4: น้อยกว่า 1 GB | X4: ไม่เกี่ยวข้อง - ไม่ใช่งานสืบค้นเอกสาร | Y4: ไม่เกี่ยวข้อง - ไม่ใช่งานประมวลผลภาพ | Z4: ติดตั้งที่ Server กลาง - ส่งข้อมูลผ่านเครือข่ายได้ | AB4: 1 ปี | AC4: ไม่ต้องฝึกโมเดล - ใช้โมเดลสำเร็จรูป | AD4: ไม่กระทบ - รอได้ ใช้งานได้ตามปกติ | AE4: ผู้ใช้เรียกใช้งานเอง - เปิดใช้เป็นครั้งคราว | AH4: Impact (ผลกระทบ) | AI4: 0.35
A5: บริษัท เอส.เค.โพลีเมอร์ จำกัด | B5: ไฟล์ Excel / CSV - นำไปใช้ได้ทันที | C5: น้อยกว่า 1 ปี - อาจไม่เพียงพอต่อการฝึกโมเดล | D5: ต้องขออนุมัติก่อน - อยู่ในความดูแลของหน่วยงานอื่นหรือ IT | E5: จำเป็นบางส่วน - เชื่อมต่อผ่านการนำเข้า/ส่งออกไฟล์เป็นรอบ | F5: ยังไม่แน่ใจ - อยู่ระหว่างจัดหาผู้รับผิดชอบ | G5: ปานกลาง - เสียเวลาดำเนินการใหม่ หรือเกิดต้นทุนเพิ่ม | H5: สุ่มตรวจบางส่วน - เฉพาะรายการที่ AI ไม่มั่นใจ | I5: ภายในองค์กร - ห้ามเผยแพร่ออกนอกบริษัท | J5: ปานกลาง - ภายในไตรมาส 2 ถึง 3 | K5: ภาพถ่าย | L5: อังกฤษ | M5: เร็ว - 2 ถึง 10 วินาที (ผู้ใช้รอที่หน้าจอได้) | N5: ขยายเวลา 6:00 - 22:00 น. | O5: ต่ำกว่า 1 ล้านพิกเซล | Q5: ไม่ต้องฝึกโมเดล แต่ให้เข้าถึงเอกสารขององค์กร (RAG) | R5: 4 - 10 ชั่วโมง/สัปดาห์ (ประมาณ 1 วันทำงาน) | S5: น้อยกว่า 100,000 บาท/ปี | T5: 11 - 50 คน | U5: 3 - 5 คน | V5: 100 - 1,000 รายการ | W5: 1 - 10 GB | X5: น้อยกว่า 1 GB | Y5: 1 จุด | Z5: ต้องติดตั้งที่หน้างาน - ติดตั้งข้างเครื่องจักรหรือสายพาน | AB5: 2 - 3 ปี | AC5: ครั้งเดียว - ฝึกเสร็จแล้วใช้งานต่อเนื่อง | AD5: กระทบบ้าง - ช่วงเร่งด่วนต้องได้รับความสำคัญก่อน | AE5: ทำงานอัตโนมัติต่อเนื่อง - ระบบทำงานเอง ไม่มีผู้เรียกใช้ | AH5: Feasibility (ความเป็นไปได้) | AI5: 0.25
A6: บริษัท ไทยรับเทค จำกัด | B6: ฐานข้อมูลในระบบ (ERP / MES / SQL) - ดึงข้อมูลอัตโนมัติได้ | C6: 1 - 3 ปี - เพียงพอในระดับหนึ่ง | D6: ไม่สามารถขอได้ หรือยังไม่แน่ใจ - เป็นของลูกค้าหรือผู้ขาย | E6: จำเป็น - ต้องอ่านและเขียนข้อมูลกับระบบเดิมแบบทันที | F6: ไม่มี - ต้องพึ่งพาหน่วยงานภายนอกตลอด | G6: สูง - ของเสียถึงมือลูกค้า เกิดอันตราย หรือผิดข้อกำหนดกฎหมาย | H6: ตรวจสอบทุกรายการ - บุคลากรต้องตรวจซ้ำทั้งหมด | I6: ลับ - ต้องจำกัดสิทธิ์การเข้าถึง | J6: ต่ำ - ดำเนินการได้ภายหลัง | K6: เสียง | L6: ไทยและอังกฤษ | M6: ภายในไม่กี่นาที | N6: ตลอด 24 ชั่วโมง ทุกวัน | O6: 1 - 5 ล้านพิกเซล | Q6: จำเป็น - ต้อง Fine-tune ด้วยข้อมูลหรือภาพขององค์กร | R6: 10 - 20 ชั่วโมง/สัปดาห์ (ประมาณ 2 วันทำงาน) | S6: 100,000 - 500,000 บาท/ปี | T6: 51 - 200 คน | U6: 6 - 20 คน | V6: 1,000 - 10,000 รายการ | W6: 10 - 100 GB | X6: 1 - 10 GB | Y6: 2 - 3 จุด | Z6: ยังไม่สามารถระบุได้ | AB6: 5 ปี | AC6: ปีละครั้ง | AD6: กระทบมาก - ไม่สามารถล่าช้าหรือหยุดได้ (อยู่ในสายการผลิต) | AE6: ประมวลผลตามรอบเวลา - เช่น ทุกคืน หรือทุกสัปดาห์ | AH6: Data (ความพร้อมข้อมูล) | AI6: 0.25
